Workbook
Name Anderthalbhänder: Waffen!$B$4:$B$8
Name Dolche: Waffen!$B$9:$B$27
Name Fechtwaffen: Waffen!$B$28:$B$36
Name Fernkampftalente: Kampftechniken!$B$24:$B$33
Name Hände: Waffen!$B$156
Name Hiebwaffen: Waffen!$B$37:$B$61
Name Infanteriewaffen: Waffen!$B$62:$B$73
Name Kettenstäbe: Waffen!$B$74:$B$75
Name Kettenwaffen: Waffen!$B$76:$B$81
Name Lanzenreiten: Waffen!$B$82:$B$84
Name Lernkomplexität: Rechner!$A$17:$B$25
Name ManoeverTabelle: Nahkampfwaffen[[Ausfall]:[Wuchtschlag]]
Name Nahkampftalente: Kampftechniken!$B$4:$B$20
Name NahkampfWaffenTabelle: Nahkampfwaffen[Waffe]
Name Peitsche: Waffen!$B$85
Name Raufen: Waffen!$B$156
Name Ringen: Waffen!$B$157
Name Säbel: Waffen!$B$86:$B$98
Name Schwerter: Waffen!$B$99:$B$112
Name Speere: Waffen!$B$113:$B$127
Name Stäbe: Waffen!$B$128:$B$130
Name Zweihand_Hiebwaffen: Waffen!$B$133:$B$146
Name Zweihandflegel: Waffen!$B$131:$B$132
Name Zweihandschwerter_Säbel: Waffen!$B$147:$B$155

Sheet Eigenschaften
B2: HELDENDOKUMENT
B3: Name | C3: Gerajin Sirella von Tuzak
B4: Rasse | C4: Mittelländer+ | K4: (Modifikationen): | M4: CH+1,LE+12,
B5: Kultur | C5: Maraskan | K5: (Modifikationen): | M5: IN+1, MR+1,
B6: Profession | C6: Hexe: Verschwiegende Hexe | K6: (Modifikationen): | M6: MR+2,AE+13,
B8: Geschlecht | C8: Männlich (Non-Binär) | K8: Stand
B9: Alter | C9: 21 (21. Ingrimm 1015 BF) | K9: Titel
B10: Größe | C10: 177 | K10: Sozialstatus | M10: 3
B11: Gewicht | C11: 70 | K11: Familie/Herkunft/Hintergrund
B12: Haarfarbe | C12: Silber | K12: CH steigern nach G
B13: Augenfarbe
B14: Aussehen
B15: Lange Haare, schmale Gesichtsform, weibliche Züge
B17: Eigenschaften & Basiswerte
D19: Modifikator aus Generierung | E19: Attributo | F19: Start | G19: Aktuell | H19: Calc | I19: Max. Wert | N19: Modifikator | O19: Start | P19: Aktuell | Q19: Zugekauft | R19: Max. Zug.
B20: Mut | C20: MU | D20: =IF(ISNUMBER((SEARCH(C20,$M$4))),_xlfn.NUMBERVALUE(MID($M$4,SEARCH(C20,$M$4)+2,2)),0)+IF(ISNUMBER((SEARCH(C20,$M$5))),_xlfn.NUMBERVALUE(MID($M$5,SEARCH(C20,$M$5)+2,2)),0)+IF(ISNUMBER((SEARCH(C20,$O$6))),_xlfn.NUMBERVALUE(MID($O$6,SEARCH(C20,$O$6)+2,2)),0) -> 0 | E20: 0 | F20: 13 | G20: 13 | H20: =G20+E20 -> 13 | I20: =ROUND((D20+F20)*1.5,0) -> 20 | K20: Lebenspunkte | L20: LE | M20: (KO+KO+KK)/2 | N20: =IF(NOT(ISERROR(FIND(L20,$M$4))),_xlfn.NUMBERVALUE(MID($M$4,FIND(L20,$M$4)+LEN(L20),FIND(",",$M$4,FIND(L20,$M$4))-FIND(L20,$M$4)-LEN(L20))),0)+IF(NOT(ISERROR(FIND(L20,$M$5))),_xlfn.NUMBERVALUE(MID($M$5,FIND(L20,$M$5)+LEN(L20),FIND(",",$M$5,FIND(L20,$M$5))-FIND(L20,$M$5)-LEN(L20))),0)+IF(NOT(ISERROR(FIND(L20,$M$6))),_xlfn.NUMBERVALUE(MID($M$6,FIND(L20,$M$6)+LEN(L20),FIND(",",$M$6,FIND(L20,$M$6))-FIND(L20,$M$6)-LEN(L20))),0)+IF(NOT(ISERROR(FIND(L20,$B$33))),_xlfn.NUMBERVALUE(MID($B$33,FIND(L20,$B$33)+LEN(L20),FIND(",",$B$33,FIND(L20,$B$33))-FIND(L20,$B$33)-LEN(L20))),0)+IF(NOT(ISERROR(FIND(L20,$B$37))),_xlfn.NUMBERVALUE(MID($B$37,FIND(L20,$B$37)+LEN(L20),FIND(",",$B$37,FIND(L20,$B$37))-FIND(L20,$B$37)-LEN(L20))),0) -> 12 | O20: =SUM((G26+G26+G27)/2) -> 18 | P20: =ROUND(IF(Q41>21,21,Q41)+N20+O20+Q20,0) -> 37 | Q20: 0 | R20: =ROUND(G26/2,0) -> 6
B21: Klugheit | C21: KL | D21: =IF(ISNUMBER((SEARCH(C21,$M$4))),_xlfn.NUMBERVALUE(MID($M$4,SEARCH(C21,$M$4)+2,2)),0)+IF(ISNUMBER((SEARCH(C21,$M$5))),_xlfn.NUMBERVALUE(MID($M$5,SEARCH(C21,$M$5)+2,2)),0)+IF(ISNUMBER((SEARCH(C21,$O$6))),_xlfn.NUMBERVALUE(MID($O$6,SEARCH(C21,$O$6)+2,2)),0) -> 0 | E21: 0 | F21: 12 | G21: 12 | H21: =G21+E21 -> 12 | I21: =ROUND((D21+F21)*1.5,0) -> 18 | K21: Ausdauer | L21: AU | M21: (MU+KO+GE)/2 | N21: =IF(NOT(ISERROR(FIND(L21,$M$4))),_xlfn.NUMBERVALUE(MID($M$4,FIND(L21,$M$4)+LEN(L21),FIND(",",$M$4,FIND(L21,$M$4))-FIND(L21,$M$4)-LEN(L21))),0)+IF(NOT(ISERROR(FIND(L21,$M$5))),_xlfn.NUMBERVALUE(MID($M$5,FIND(L21,$M$5)+LEN(L21),FIND(",",$M$5,FIND(L21,$M$5))-FIND(L21,$M$5)-LEN(L21))),0)+IF(NOT(ISERROR(FIND(L21,$M$6))),_xlfn.NUMBERVALUE(MID($M$6,FIND(L21,$M$6)+LEN(L21),FIND(",",$M$6,FIND(L21,$M$6))-FIND(L21,$M$6)-LEN(L21))),0)+IF(NOT(ISERROR(FIND(L21,$B$33))),_xlfn.NUMBERVALUE(MID($B$33,FIND(L21,$B$33)+LEN(L21),FIND(",",$B$33,FIND(L21,$B$33))-FIND(L21,$B$33)-LEN(L21))),0)+IF(NOT(ISERROR(FIND(L21,$B$37))),_xlfn.NUMBERVALUE(MID($B$37,FIND(L21,$B$37)+LEN(L21),FIND(",",$B$37,FIND(L21,$B$37))-FIND(L21,$B$37)-LEN(L21))),0) -> 0 | O21: =SUM((G20+G26+G25)/2) -> 19.5 | P21: =ROUND(SUM(N21+O21+Q21+2*Q41),0) -> 34 | Q21: 0 | R21: =ROUND(G26*2,0) -> 24
B22: Intuition | C22: IN | D22: =IF(ISNUMBER((SEARCH(C22,$M$4))),_xlfn.NUMBERVALUE(MID($M$4,SEARCH(C22,$M$4)+2,2)),0)+IF(ISNUMBER((SEARCH(C22,$M$5))),_xlfn.NUMBERVALUE(MID($M$5,SEARCH(C22,$M$5)+2,2)),0)+IF(ISNUMBER((SEARCH(C22,$O$6))),_xlfn.NUMBERVALUE(MID($O$6,SEARCH(C22,$O$6)+2,2)),0) -> 1 | E22: 0 | F22: 15 | G22: 15 | H22: =G22+E22 -> 15 | I22: =ROUND((D22+F22)*1.5,0) -> 24 | K22: Astralenergie | L22: AE | M22: (MU+IN+CH)/2 | N22: =IF(NOT(ISERROR(FIND(L22,$M$4))),_xlfn.NUMBERVALUE(MID($M$4,FIND(L22,$M$4)+LEN(L22),FIND(",",$M$4,FIND(L22,$M$4))-FIND(L22,$M$4)-LEN(L22))),0)+IF(NOT(ISERROR(FIND(L22,$M$5))),_xlfn.NUMBERVALUE(MID($M$5,FIND(L22,$M$5)+LEN(L22),FIND(",",$M$5,FIND(L22,$M$5))-FIND(L22,$M$5)-LEN(L22))),0)+IF(NOT(ISERROR(FIND(L22,$M$6))),_xlfn.NUMBERVALUE(MID($M$6,FIND(L22,$M$6)+LEN(L22),FIND(",",$M$6,FIND(L22,$M$6))-FIND(L22,$M$6)-LEN(L22))),0)+IF(NOT(ISERROR(FIND(L22,$B$33))),_xlfn.NUMBERVALUE(MID($B$33,FIND(L22,$B$33)+LEN(L22),FIND(",",$B$33,FIND(L22,$B$33))-FIND(L22,$B$33)-LEN(L22))),0)+IF(NOT(ISERROR(FIND(L22,$B$37))),_xlfn.NUMBERVALUE(MID($B$37,FIND(L22,$B$37)+LEN(L22),FIND(",",$B$37,FIND(L22,$B$37))-FIND(L22,$B$37)-LEN(L22))),0) -> 13 | O22: =IF(N22=0,"",SUM((G20+G22+G23)/2)+N22) -> 34.5 | P22: =IF(N22=0,"",ROUND(O22+2*Q41,0)) -> 49 | Q22: 0
B23: Charisma | C23: CH | D23: =IF(ISNUMBER((SEARCH(C23,$M$4))),_xlfn.NUMBERVALUE(MID($M$4,SEARCH(C23,$M$4)+2,2)),0)+IF(ISNUMBER((SEARCH(C23,$M$5))),_xlfn.NUMBERVALUE(MID($M$5,SEARCH(C23,$M$5)+2,2)),0)+IF(ISNUMBER((SEARCH(C23,$O$6))),_xlfn.NUMBERVALUE(MID($O$6,SEARCH(C23,$O$6)+2,2)),0) -> 1 | E23: 0 | F23: 15 | G23: 15 | H23: =G23+E23 -> 15 | I23: =ROUND((D23+F23)*1.5,0) -> 24 | K23: Karmaenergie | L23: KE | M23: CH | N23: =IF(NOT(ISERROR(FIND(L23,$M$4))),_xlfn.NUMBERVALUE(MID($M$4,FIND(L23,$M$4)+LEN(L23),FIND(",",$M$4,FIND(L23,$M$4))-FIND(L23,$M$4)-LEN(L23))),0)+IF(NOT(ISERROR(FIND(L23,$M$5))),_xlfn.NUMBERVALUE(MID($M$5,FIND(L23,$M$5)+LEN(L23),FIND(",",$M$5,FIND(L23,$M$5))-FIND(L23,$M$5)-LEN(L23))),0)+IF(NOT(ISERROR(FIND(L23,$M$6))),_xlfn.NUMBERVALUE(MID($M$6,FIND(L23,$M$6)+LEN(L23),FIND(",",$M$6,FIND(L23,$M$6))-FIND(L23,$M$6)-LEN(L23))),0)+IF(NOT(ISERROR(FIND(L23,$B$33))),_xlfn.NUMBERVALUE(MID($B$33,FIND(L23,$B$33)+LEN(L23),FIND(",",$B$33,FIND(L23,$B$33))-FIND(L23,$B$33)-LEN(L23))),0)+IF(NOT(ISERROR(FIND(L23,$B$37))),_xlfn.NUMBERVALUE(MID($B$37,FIND(L23,$B$37)+LEN(L23),FIND(",",$B$37,FIND(L23,$B$37))-FIND(L23,$B$37)-LEN(L23))),0) -> 0 | O23: 3 | P23: =IF(N23=0,"",ROUND((SUM(N23+O23+Q23+2*Q41)),0)) | Q23: 0
B24: Fingerfertigkeit | C24: FF | D24: =IF(ISNUMBER((SEARCH(C24,$M$4))),_xlfn.NUMBERVALUE(MID($M$4,SEARCH(C24,$M$4)+2,2)),0)+IF(ISNUMBER((SEARCH(C24,$M$5))),_xlfn.NUMBERVALUE(MID($M$5,SEARCH(C24,$M$5)+2,2)),0)+IF(ISNUMBER((SEARCH(C24,$O$6))),_xlfn.NUMBERVALUE(MID($O$6,SEARCH(C24,$O$6)+2,2)),0) -> 0 | E24: 0 | F24: 10 | G24: 10 | H24: =G24+E24 -> 10 | I24: =ROUND((D24+F24)*1.5,0) -> 15 | K24: Magieresistenz | L24: MR | M24: (MU+KL+KO)/5 | N24: =IF(NOT(ISERROR(FIND(L24,$M$4))),_xlfn.NUMBERVALUE(MID($M$4,FIND(L24,$M$4)+LEN(L24),FIND(",",$M$4,FIND(L24,$M$4))-FIND(L24,$M$4)-LEN(L24))),0)+IF(NOT(ISERROR(FIND(L24,$M$5))),_xlfn.NUMBERVALUE(MID($M$5,FIND(L24,$M$5)+LEN(L24),FIND(",",$M$5,FIND(L24,$M$5))-FIND(L24,$M$5)-LEN(L24))),0)+IF(NOT(ISERROR(FIND(L24,$M$6))),_xlfn.NUMBERVALUE(MID($M$6,FIND(L24,$M$6)+LEN(L24),FIND(",",$M$6,FIND(L24,$M$6))-FIND(L24,$M$6)-LEN(L24))),0)+IF(NOT(ISERROR(FIND(L24,$B$33))),_xlfn.NUMBERVALUE(MID($B$33,FIND(L24,$B$33)+LEN(L24),FIND(",",$B$33,FIND(L24,$B$33))-FIND(L24,$B$33)-LEN(L24))),0)+IF(NOT(ISERROR(FIND(L24,$B$37))),_xlfn.NUMBERVALUE(MID($B$37,FIND(L24,$B$37)+LEN(L24),FIND(",",$B$37,FIND(L24,$B$37))-FIND(L24,$B$37)-LEN(L24))),0) -> 3 | O24: =SUM((H20+H21+H26)/5) -> 7.4 | P24: =ROUND(SUM(N24+O24+Q24),0) -> 10 | Q24: 0 | R24: =ROUND(G20/2,0) -> 7
B25: Gewandheit | C25: GE | D25: =IF(ISNUMBER((SEARCH(C25,$M$4))),_xlfn.NUMBERVALUE(MID($M$4,SEARCH(C25,$M$4)+2,2)),0)+IF(ISNUMBER((SEARCH(C25,$M$5))),_xlfn.NUMBERVALUE(MID($M$5,SEARCH(C25,$M$5)+2,2)),0)+IF(ISNUMBER((SEARCH(C25,$O$6))),_xlfn.NUMBERVALUE(MID($O$6,SEARCH(C25,$O$6)+2,2)),0) -> 0 | E25: 0 | F25: 14 | G25: 14 | H25: =G25+E25 -> 14 | I25: =ROUND((D25+F25)*1.5,0) -> 21 | K25: INI-Basiswert | L25: INI | M25: (MU+MU+IN+GE)/5 | N25: 0 | O25: =SUM((H20+H20+H22+H25)/5) -> 11 | P25: =ROUND(SUM(N25+O25),0) -> 11
B26: Konstitution | C26: KO | D26: =IF(ISNUMBER((SEARCH(C26,$M$4))),_xlfn.NUMBERVALUE(MID($M$4,SEARCH(C26,$M$4)+2,2)),0)+IF(ISNUMBER((SEARCH(C26,$M$5))),_xlfn.NUMBERVALUE(MID($M$5,SEARCH(C26,$M$5)+2,2)),0)+IF(ISNUMBER((SEARCH(C26,$O$6))),_xlfn.NUMBERVALUE(MID($O$6,SEARCH(C26,$O$6)+2,2)),0) -> 0 | E26: 0 | F26: 12 | G26: 12 | H26: =G26+E26 -> 12 | I26: =ROUND((D26+F26)*1.5,0) -> 18 | K26: AT-Basiswert | L26: AT | M26: (MU+GE+KK)/5 | N26: =IF(NOT(ISERROR(FIND(L26,$M$4))),_xlfn.NUMBERVALUE(MID($M$4,FIND(L26,$M$4)+LEN(L26),FIND(",",$M$4,FIND(L26,$M$4))-FIND(L26,$M$4)-LEN(L26))),0)+IF(NOT(ISERROR(FIND(L26,$M$5))),_xlfn.NUMBERVALUE(MID($M$5,FIND(L26,$M$5)+LEN(L26),FIND(",",$M$5,FIND(L26,$M$5))-FIND(L26,$M$5)-LEN(L26))),0)+IF(NOT(ISERROR(FIND(L26,$M$6))),_xlfn.NUMBERVALUE(MID($M$6,FIND(L26,$M$6)+LEN(L26),FIND(",",$M$6,FIND(L26,$M$6))-FIND(L26,$M$6)-LEN(L26))),0)+IF(NOT(ISERROR(FIND(L26,$B$33))),_xlfn.NUMBERVALUE(MID($B$33,FIND(L26,$B$33)+LEN(L26),FIND(",",$B$33,FIND(L26,$B$33))-FIND(L26,$B$33)-LEN(L26))),0)+IF(NOT(ISERROR(FIND(L26,$B$37))),_xlfn.NUMBERVALUE(MID($B$37,FIND(L26,$B$37)+LEN(L26),FIND(",",$B$37,FIND(L26,$B$37))-FIND(L26,$B$37)-LEN(L26))),0) -> 0 | O26: =SUM((H20+H25+H27)/5)+N26 -> 7.8 | P26: =ROUND(SUM(N26+O26),0) -> 8
B27: Körperkraft | C27: KK | D27: =IF(ISNUMBER((SEARCH(C27,$M$4))),_xlfn.NUMBERVALUE(MID($M$4,SEARCH(C27,$M$4)+2,2)),0)+IF(ISNUMBER((SEARCH(C27,$M$5))),_xlfn.NUMBERVALUE(MID($M$5,SEARCH(C27,$M$5)+2,2)),0)+IF(ISNUMBER((SEARCH(C27,$O$6))),_xlfn.NUMBERVALUE(MID($O$6,SEARCH(C27,$O$6)+2,2)),0) -> 0 | E27: 0 | F27: 12 | G27: 12 | H27: =G27+E27 -> 12 | I27: =ROUND((D27+F27)*1.5,0) -> 18 | K27: PA-Basiswert | L27: PA | M27: (IN+GE+KK)/5 | N27: =IF(NOT(ISERROR(FIND(L27,$M$4))),_xlfn.NUMBERVALUE(MID($M$4,FIND(L27,$M$4)+LEN(L27),FIND(",",$M$4,FIND(L27,$M$4))-FIND(L27,$M$4)-LEN(L27))),0)+IF(NOT(ISERROR(FIND(L27,$M$5))),_xlfn.NUMBERVALUE(MID($M$5,FIND(L27,$M$5)+LEN(L27),FIND(",",$M$5,FIND(L27,$M$5))-FIND(L27,$M$5)-LEN(L27))),0)+IF(NOT(ISERROR(FIND(L27,$M$6))),_xlfn.NUMBERVALUE(MID($M$6,FIND(L27,$M$6)+LEN(L27),FIND(",",$M$6,FIND(L27,$M$6))-FIND(L27,$M$6)-LEN(L27))),0)+IF(NOT(ISERROR(FIND(L27,$B$33))),_xlfn.NUMBERVALUE(MID($B$33,FIND(L27,$B$33)+LEN(L27),FIND(",",$B$33,FIND(L27,$B$33))-FIND(L27,$B$33)-LEN(L27))),0)+IF(NOT(ISERROR(FIND(L27,$B$37))),_xlfn.NUMBERVALUE(MID($B$37,FIND(L27,$B$37)+LEN(L27),FIND(",",$B$37,FIND(L27,$B$37))-FIND(L27,$B$37)-LEN(L27))),0)+IF(Nahkampf!$C$5="Ja",2,0) -> 0 | O27: =SUM((H22+H25+H27)/5) -> 8.2 | P27: =ROUND(SUM(N27+O27),0) -> 8
K28: FK-Basiswert | L28: FK | M28: (IN+FF+KK)/5 | N28: =IF(NOT(ISERROR(FIND(L28,$M$4))),_xlfn.NUMBERVALUE(MID($M$4,FIND(L28,$M$4)+LEN(L28),FIND(",",$M$4,FIND(L28,$M$4))-FIND(L28,$M$4)-LEN(L28))),0)+IF(NOT(ISERROR(FIND(L28,$M$5))),_xlfn.NUMBERVALUE(MID($M$5,FIND(L28,$M$5)+LEN(L28),FIND(",",$M$5,FIND(L28,$M$5))-FIND(L28,$M$5)-LEN(L28))),0)+IF(NOT(ISERROR(FIND(L28,$M$6))),_xlfn.NUMBERVALUE(MID($M$6,FIND(L28,$M$6)+LEN(L28),FIND(",",$M$6,FIND(L28,$M$6))-FIND(L28,$M$6)-LEN(L28))),0)+IF(NOT(ISERROR(FIND(L28,$B$33))),_xlfn.NUMBERVALUE(MID($B$33,FIND(L28,$B$33)+LEN(L28),FIND(",",$B$33,FIND(L28,$B$33))-FIND(L28,$B$33)-LEN(L28))),0)+IF(NOT(ISERROR(FIND(L28,$B$37))),_xlfn.NUMBERVALUE(MID($B$37,FIND(L28,$B$37)+LEN(L28),FIND(",",$B$37,FIND(L28,$B$37))-FIND(L28,$B$37)-LEN(L28))),0) -> 0 | O28: =SUM((H22+H24+H27)/5) -> 7.4 | P28: =ROUND(SUM(N28+O28),0) -> 7
K29: Geschwindigkeit | L29: GES | M29: (GE<11:-1 | GE>15:+1) | N29: =IF(NOT(ISERROR(FIND(L29,$M$4))),_xlfn.NUMBERVALUE(MID($M$4,FIND(L29,$M$4)+LEN(L29),FIND(",",$M$4,FIND(L29,$M$4))-FIND(L29,$M$4)-LEN(L29))),0)+IF(NOT(ISERROR(FIND(L29,$M$5))),_xlfn.NUMBERVALUE(MID($M$5,FIND(L29,$M$5)+LEN(L29),FIND(",",$M$5,FIND(L29,$M$5))-FIND(L29,$M$5)-LEN(L29))),0)+IF(NOT(ISERROR(FIND(L29,$M$6))),_xlfn.NUMBERVALUE(MID($M$6,FIND(L29,$M$6)+LEN(L29),FIND(",",$M$6,FIND(L29,$M$6))-FIND(L29,$M$6)-LEN(L29))),0)+IF(NOT(ISERROR(FIND(L29,$B$33))),_xlfn.NUMBERVALUE(MID($B$33,FIND(L29,$B$33)+LEN(L29),FIND(",",$B$33,FIND(L29,$B$33))-FIND(L29,$B$33)-LEN(L29))),0)+IF(NOT(ISERROR(FIND(L29,$B$37))),_xlfn.NUMBERVALUE(MID($B$37,FIND(L29,$B$37)+LEN(L29),FIND(",",$B$37,FIND(L29,$B$37))-FIND(L29,$B$37)-LEN(L29))),0)+IF(Nahkampf!$C$5="Ja",Eigenschaften!O29-Nahkampf!AR16,0) -> 0 | O29: =IF($G$25<11,7,IF($G$25>15,9,8))+IF(Nahkampf!AJ36=TRUE,1,0)+IF(Nahkampf!AJ37=TRUE,-1,0) -> 8 | P29: =ROUND(O29+N29-Nahkampf!AR16,0) -> 7
K30: Limbus | M30: (MU/IN/GE)/5 | O30: =(H20+H22+H25)/5 -> 8.4 | P30: =ROUND(O30,0) -> 8
B31: Vorteile
B33: Altersresistenz, Eigeboren, Gutaussehend, Machvoller Vertrauter, Verhüllte Aura, Vollzauberer, Begabung Alchemie,
B35: Nachteile
B37: Arroganz 6, Brünstigkeit 8, Eitelkeit 7, Feste Gewohnheit (Erdgebundenheit), Gesucht 1 (Praois Kirche auf Maraskan), Kälteempfindlich, Medium, Neugier 8, Rachsucht 9, Randgruppe, Voruteile Praios-Geweihte 8,
B39: Abentuerpunkte & Stufe
B41: Gesamt: | D41: 2573 | G41: Eingesetzte AP: | K41: 2571 | M41: Guthaben: | N41: =D41-K41 -> 2 | P41: Stufe: | Q41: =ROUNDDOWN((SQRT(K41/50+0.25)+0.5),0) -> 7
B42: Dazugewonnene AP: | D42: 0 | G42: Ausgegebene AP: | K42: 0
B43: Errechnete neue AP: | D43: =D41+D42 -> 2573 | G43: Errechnete ausgegebene AP: | K43: =K41+K42 -> 2571
C45: Maximum | D45: 1/2 | E45: 1/3 | F45: 1/4 | G45: Aktuell | J45: Maximum | K45: Aktuell
B46: Lebensenergie | C46: =Eigenschaften!P20 -> 37 | D46: =ROUND(C46/2,0) -> 19 | E46: =ROUND(C46/3,0) -> 12 | F46: =ROUND(C46/4,0) -> 9 | H46: Astralenergie | J46: =Eigenschaften!P22 -> 49 | K46: 40
B47: Ausdauer | C47: =Eigenschaften!P21 -> 34 | D47: =ROUND(C47/2,0) -> 17 | E47: =ROUND(C47/3,0) -> 11 | F47: =ROUND(C47/4,0) -> 9 | H47: Karmalenergie | J47: - | K47: - | O47: =Eigenschaften!P23

Sheet Talente
A1: Name | B1: Typ | C1: EiGewandheitnsCharismaaft 1 | D1: EiGewandheitnsCharismaaft 2 | E1: EiGewandheitnsCharismaaft 3 | F1: Komplexität | G1: BE
A2: Empathie | B2: Gabe | C2: Mut | D2: Intuition | E2: Intuition
A3: Gefahreninstinkt | B3: Gabe | C3: Klugheit | D3: Intuition | E3: Intuition
A4: Geräuschhexerei | B4: Gabe | C4: Intuition | D4: Charisma | E4: Konstitution
A5: Kräfteschub | B5: Gabe | C5: Mut | D5: Intuition | E5: Konstitution
A6: Talentschub | B6: Gabe | C6: Mut | D6: Intuition | E6: Konstitution
A7: Magiegespür | B7: Gabe | C7: Mut | D7: Intuition | E7: Intuition
A8: Prophezeien | B8: Gabe | C8: Intuition | D8: Intuition | E8: Charisma
A9: Tierempathie | B9: Gabe | C9: Mut | D9: Intuition | E9: Charisma
A10: Zwergennase | B10: Gabe | C10: Intuition | D10: Intuition | E10: Fingerfertigkeit
A11: Athletik | B11: Körperliche Talente | C11: Gewandheit | D11: Konstitution | E11: Körperkraft | F11: C | G11: x2
A12: Klettern | B12: Körperliche Talente | C12: Mut | D12: Gewandheit | E12: Körperkraft | F12: D | G12: x2
A13: Körperbeherrschung | B13: Körperliche Talente | C13: Mut | D13: Intuition | E13: Gewandheit | F13: D | G13: x2
A14: Schleichen | B14: Körperliche Talente | C14: Mut | D14: Intuition | E14: Gewandheit | F14: C | G14: x1
A15: Schwimmen | B15: Körperliche Talente | C15: Gewandheit | D15: Konstitution | E15: Körperkraft | F15: D | G15: x2
A16: Selbstbeherrschung | B16: Körperliche Talente | C16: Mut | D16: Konstitution | E16: Körperkraft | F16: D | G16: -
A17: Sich Verstecken | B17: Körperliche Talente | C17: Mut | D17: Intuition | E17: Gewandheit | F17: C | G17: -2
A18: Singen | B18: Körperliche Talente | C18: Intuition | D18: Charisma | E18: Charisma | F18: C | G18: -3
A19: Sinnesschärfe | B19: Körperliche Talente | C19: Klugheit | D19: Intuition | E19: Intuition | F19: D | G19: spez.
A20: Tanzen | B20: Körperliche Talente | C20: Charisma | D20: Gewandheit | E20: Gewandheit | F20: B | G20: x2
A21: Zechen | B21: Körperliche Talente | C21: Intuition | D21: Konstitution | E21: Körperkraft | F21: B | G21: -
A22: Akrobatik | B22: Körperliche Talente | C22: Mut | D22: Gewandheit | E22: Körperkraft | F22: A | G22: x2
A23: Fliegen | B23: Körperliche Talente | C23: Mut | D23: Intuition | E23: Gewandheit | F23: D | G23: x1
A24: Gaukeleien | B24: Körperliche Talente | C24: Mut | D24: Charisma | E24: Fingerfertigkeit | F24: C | G24: x2
A25: Reiten | B25: Körperliche Talente | C25: Charisma | D25: Gewandheit | E25: Körperkraft | F25: D | G25: -2
A26: Skifahren | B26: Körperliche Talente | C26: Gewandheit | D26: Gewandheit | E26: Konstitution | F26: B | G26: -2
A27: Stimmen Imitieren | B27: Körperliche Talente | C27: Klugheit | D27: Intuition | E27: Charisma | F27: C | G27: -4
A28: Taschendiebstahl | B28: Körperliche Talente | C28: Mut | D28: Intuition | E28: Fingerfertigkeit | F28: C | G28: x2
A29: Götter / Kulte | B29: Wissenstalente | C29: Klugheit | D29: Klugheit | E29: Intuition | F29: B | G29: -
A30: Rechnen | B30: Wissenstalente | C30: Klugheit | D30: Klugheit | E30: Intuition | F30: B | G30: -
A31: Sagen / Legenden | B31: Wissenstalente | C31: Klugheit | D31: Intuition | E31: Charisma | F31: B | G31: -
A32: Anatomie | B32: Wissenstalente | C32: Mut | D32: Klugheit | E32: Fingerfertigkeit | F32: B | G32: -
A33: Baukunst | B33: Wissenstalente | C33: Klugheit | D33: Klugheit | E33: Fingerfertigkeit | F33: B | G33: -
A34: Brett-/Kartenspiel | B34: Wissenstalente | C34: Klugheit | D34: Klugheit | E34: Intuition | F34: B | G34: -
A35: Geographie | B35: Wissenstalente | C35: Klugheit | D35: Klugheit | E35: Intuition | F35: B | G35: -
A36: Geschichtswissen | B36: Wissenstalente | C36: Klugheit | D36: Klugheit | E36: Intuition | F36: B | G36: -
A37: Gesteinskunde | B37: Wissenstalente | C37: Klugheit | D37: Intuition | E37: Fingerfertigkeit | F37: B | G37: -
A38: Heraldik | B38: Wissenstalente | C38: Klugheit | D38: Klugheit | E38: Fingerfertigkeit | F38: B | G38: -
A39: Hüttenkunde | B39: Wissenstalente | C39: Klugheit | D39: Intuition | E39: Konstitution | F39: B | G39: -
... A115: Zimmermann | B115: Handwerkliche Talente | C115: Klugheit | D115: Fingerfertigkeit | E115: Körperkraft | F115: B | G115: -

Sheet Fertigkeiten & Talente
B1: Talente, Gaben und Sonderfertigkeiten
C2: BE (aus Kampfblatt): | D2: =Nahkampf!AR16 -> 1 | E2: BE (manuell): | F2: =IF(ISNUMBER(L2),L2,"") | G2: BE (Berechnung): | H2: =IF(ISNUMBER(F2),F2,D2) -> 1 | I2: BE (Überschreiben):
B3: Talent | C3: Eigenschaft 1 | D3: Eigenschaft 1 | E3: Eigenschaft 2 | F3: Eigenschaft 2 | G3: Eigenschaft 3 | H3: Eigenschaft 3 | I3: Eigenschaften | J3: Kompl. | K3: BE | L3: eBE | M3: TaW | N3: max. TaW | O3: Mod | P3: TaW | Q3: SE | R3: Spezialisierung | S3: Sonderfertigkeiten | U3: Sonderferigkeiten (außer Kampf)
B4: Akrobatik | C4: =_xlfn.XLOOKUP(B4,Talente!A:A,Talente!C:C) -> Mut | D4: =_xlfn.XLOOKUP(C4,Eigenschaften!$B$20:$B$27,Eigenschaften!$H$20:$H$27,"NaN",1) -> 13 | E4: =_xlfn.XLOOKUP(B4,Talente!A:A,Talente!D:D) -> Gewandheit | F4: =_xlfn.XLOOKUP(E4,Eigenschaften!$B$20:$B$27,Eigenschaften!$H$20:$H$27,"NaN",1) -> 14 | G4: =_xlfn.XLOOKUP(B4,Talente!A:A,Talente!E:E) -> Körperkraft | H4: =_xlfn.XLOOKUP(G4,Eigenschaften!$B$20:$B$27,Eigenschaften!$H$20:$H$27,"NaN",1) -> 12 | I4: =C4&": "&D4&" | "&E4&": "&F4&" | "&G4&": "&H4 -> Mut: 13 | Gewandheit: 14 | Körperkraft: 12 | J4: =_xlfn.XLOOKUP(B4,Talente!A:A,Talente!F:F) -> A | K4: =_xlfn.XLOOKUP(B4,Talente!A:A,Talente!G:G) -> x2 | L4: =IF(NOT(ISERROR(FIND("x",K4))),RIGHT(K4,1)*$H$2,IF(K4<0,IF(($H$2+K4)>0,$H$2+K4,0),IF(K4="-",0,0))) -> 2 | N4: =MAX(D4:H4)+3 -> 17 | O4: 0 | P4: =IF(M4="-","-",M4-L4+O4) -> -2 | U4: Kulturkunde Maraskan, Aura verhüllen
B5: Athletik | C5: =_xlfn.XLOOKUP(B5,Talente!A:A,Talente!C:C) -> Gewandheit | D5: =_xlfn.XLOOKUP(C5,Eigenschaften!$B$20:$B$27,Eigenschaften!$H$20:$H$27,"NaN",1) -> 14 | E5: =_xlfn.XLOOKUP(B5,Talente!A:A,Talente!D:D) -> Konstitution | F5: =_xlfn.XLOOKUP(E5,Eigenschaften!$B$20:$B$27,Eigenschaften!$H$20:$H$27,"NaN",1) -> 12 | G5: =_xlfn.XLOOKUP(B5,Talente!A:A,Talente!E:E) -> Körperkraft | H5: =_xlfn.XLOOKUP(G5,Eigenschaften!$B$20:$B$27,Eigenschaften!$H$20:$H$27,"NaN",1) -> 12 | I5: =C5&": "&D5&" | "&E5&": "&F5&" | "&G5&": "&H5 -> Gewandheit: 14 | Konstitution: 12 | Körperkraft: 12 | J5: =_xlfn.XLOOKUP(B5,Talente!A:A,Talente!F:F) -> C | K5: =_xlfn.XLOOKUP(B5,Talente!A:A,Talente!G:G) -> x2 | L5: =IF(NOT(ISERROR(FIND("x",K5))),RIGHT(K5,1)*$H$2,IF(K5<0,IF(($H$2+K5)>0,$H$2+K5,0),IF(K5="-",0,0))) -> 2 | M5: 1 | N5: =MAX(D5:H5)+3 -> 17 | O5: 0 | P5: =IF(M5="-","-",M5-L5+O5) -> -1
B6: Fliegen | C6: =_xlfn.XLOOKUP(B6,Talente!A:A,Talente!C:C) -> Mut | D6: =_xlfn.XLOOKUP(C6,Eigenschaften!$B$20:$B$27,Eigenschaften!$H$20:$H$27,"NaN",1) -> 13 | E6: =_xlfn.XLOOKUP(B6,Talente!A:A,Talente!D:D) -> Intuition | F6: =_xlfn.XLOOKUP(E6,Eigenschaften!$B$20:$B$27,Eigenschaften!$H$20:$H$27,"NaN",1) -> 15 | G6: =_xlfn.XLOOKUP(B6,Talente!A:A,Talente!E:E) -> Gewandheit | H6: =_xlfn.XLOOKUP(G6,Eigenschaften!$B$20:$B$27,Eigenschaften!$H$20:$H$27,"NaN",1) -> 14 | I6: =C6&": "&D6&" | "&E6&": "&F6&" | "&G6&": "&H6 -> Mut: 13 | Intuition: 15 | Gewandheit: 14 | J6: =_xlfn.XLOOKUP(B6,Talente!A:A,Talente!F:F) -> D | K6: =_xlfn.XLOOKUP(B6,Talente!A:A,Talente!G:G) -> x1 | L6: =IF(NOT(ISERROR(FIND("x",K6))),RIGHT(K6,1)*$H$2,IF(K6<0,IF(($H$2+K6)>0,$H$2+K6,0),IF(K6="-",0,0))) -> 1 | M6: 7 | N6: =MAX(D6:H6)+3 -> 18 | O6: 0 | P6: =IF(M6="-","-",M6-L6+O6) -> 6
B7: Gaukeleien | C7: =_xlfn.XLOOKUP(B7,Talente!A:A,Talente!C:C) -> Mut | D7: =_xlfn.XLOOKUP(C7,Eigenschaften!$B$20:$B$27,Eigenschaften!$H$20:$H$27,"NaN",1) -> 13 | E7: =_xlfn.XLOOKUP(B7,Talente!A:A,Talente!D:D) -> Charisma | F7: =_xlfn.XLOOKUP(E7,Eigenschaften!$B$20:$B$27,Eigenschaften!$H$20:$H$27,"NaN",1) -> 15 | G7: =_xlfn.XLOOKUP(B7,Talente!A:A,Talente!E:E) -> Fingerfertigkeit | H7: =_xlfn.XLOOKUP(G7,Eigenschaften!$B$20:$B$27,Eigenschaften!$H$20:$H$27,"NaN",1) -> 10 | I7: =C7&": "&D7&" | "&E7&": "&F7&" | "&G7&": "&H7 -> Mut: 13 | Charisma: 15 | Fingerfertigkeit: 10 | J7: =_xlfn.XLOOKUP(B7,Talente!A:A,Talente!F:F) -> C | K7: =_xlfn.XLOOKUP(B7,Talente!A:A,Talente!G:G) -> x2 | L7: =IF(NOT(ISERROR(FIND("x",K7))),RIGHT(K7,1)*$H$2,IF(K7<0,IF(($H$2+K7)>0,$H$2+K7,0),IF(K7="-",0,0))) -> 2 | N7: =MAX(D7:H7)+3 -> 18 | O7: 0 | P7: =IF(M7="-","-",M7-L7+O7) -> -2
B8: Klettern | C8: =_xlfn.XLOOKUP(B8,Talente!A:A,Talente!C:C) -> Mut | D8: =_xlfn.XLOOKUP(C8,Eigenschaften!$B$20:$B$27,Eigenschaften!$H$20:$H$27,"NaN",1) -> 13 | E8: =_xlfn.XLOOKUP(B8,Talente!A:A,Talente!D:D) -> Gewandheit | F8: =_xlfn.XLOOKUP(E8,Eigenschaften!$B$20:$B$27,Eigenschaften!$H$20:$H$27,"NaN",1) -> 14 | G8: =_xlfn.XLOOKUP(B8,Talente!A:A,Talente!E:E) -> Körperkraft | H8: =_xlfn.XLOOKUP(G8,Eigenschaften!$B$20:$B$27,Eigenschaften!$H$20:$H$27,"NaN",1) -> 12 | I8: =C8&": "&D8&" | "&E8&": "&F8&" | "&G8&": "&H8 -> Mut: 13 | Gewandheit: 14 | Körperkraft: 12 | J8: =_xlfn.XLOOKUP(B8,Talente!A:A,Talente!F:F) -> D | K8: =_xlfn.XLOOKUP(B8,Talente!A:A,Talente!G:G) -> x2 | L8: =IF(NOT(ISERROR(FIND("x",K8))),RIGHT(K8,1)*$H$2,IF(K8<0,IF(($H$2+K8)>0,$H$2+K8,0),IF(K8="-",0,0))) -> 2 | M8: 3 | N8: =MAX(D8:H8)+3 -> 17 | O8: 0 | P8: =IF(M8="-","-",M8-L8+O8) -> 1
B9: Körperbeherrschung | C9: =_xlfn.XLOOKUP(B9,Talente!A:A,Talente!C:C) -> Mut | D9: =_xlfn.XLOOKUP(C9,Eigenschaften!$B$20:$B$27,Eigenschaften!$H$20:$H$27,"NaN",1) -> 13 | E9: =_xlfn.XLOOKUP(B9,Talente!A:A,Talente!D:D) -> Intuition | F9: =_xlfn.XLOOKUP(E9,Eigenschaften!$B$20:$B$27,Eigenschaften!$H$20:$H$27,"NaN",1) -> 15 | G9: =_xlfn.XLOOKUP(B9,Talente!A:A,Talente!E:E) -> Gewandheit | H9: =_xlfn.XLOOKUP(G9,Eigenschaften!$B$20:$B$27,Eigenschaften!$H$20:$H$27,"NaN",1) -> 14 | I9: =C9&": "&D9&" | "&E9&": "&F9&" | "&G9&": "&H9 -> Mut: 13 | Intuition: 15 | Gewandheit: 14 | J9: =_xlfn.XLOOKUP(B9,Talente!A:A,Talente!F:F) -> D | K9: =_xlfn.XLOOKUP(B9,Talente!A:A,Talente!G:G) -> x2 | L9: =IF(NOT(ISERROR(FIND("x",K9))),RIGHT(K9,1)*$H$2,IF(K9<0,IF(($H$2+K9)>0,$H$2+K9,0),IF(K9="-",0,0))) -> 2 | M9: 4 | N9: =MAX(D9:H9)+3 -> 18 | O9: 0 | P9: =IF(M9="-","-",M9-L9+O9) -> 2
B10: Reiten | C10: =_xlfn.XLOOKUP(B10,Talente!A:A,Talente!C:C) -> Charisma | D10: =_xlfn.XLOOKUP(C10,Eigenschaften!$B$20:$B$27,Eigenschaften!$H$20:$H$27,"NaN",1) -> 15 | E10: =_xlfn.XLOOKUP(B10,Talente!A:A,Talente!D:D) -> Gewandheit | F10: =_xlfn.XLOOKUP(E10,Eigenschaften!$B$20:$B$27,Eigenschaften!$H$20:$H$27,"NaN",1) -> 14 | G10: =_xlfn.XLOOKUP(B10,Talente!A:A,Talente!E:E) -> Körperkraft | H10: =_xlfn.XLOOKUP(G10,Eigenschaften!$B$20:$B$27,Eigenschaften!$H$20:$H$27,"NaN",1) -> 12 | I10: =C10&": "&D10&" | "&E10&": "&F10&" | "&G10&": "&H10 -> Charisma: 15 | Gewandheit: 14 | Körperkraft: 12 | J10: =_xlfn.XLOOKUP(B10,Talente!A:A,Talente!F:F) -> D | K10: =_xlfn.XLOOKUP(B10,Talente!A:A,Talente!G:G) -> -2 | L10: =IF(NOT(ISERROR(FIND("x",K10))),RIGHT(K10,1)*$H$2,IF(K10<0,IF(($H$2+K10)>0,$H$2+K10,0),IF(K10="-",0,0))) -> 0 | N10: =MAX(D10:H10)+3 -> 18 | O10: 0 | P10: =IF(M10="-","-",M10-L10+O10) -> 0
B11: Schleichen | C11: =_xlfn.XLOOKUP(B11,Talente!A:A,Talente!C:C) -> Mut | D11: =_xlfn.XLOOKUP(C11,Eigenschaften!$B$20:$B$27,Eigenschaften!$H$20:$H$27,"NaN",1) -> 13 | E11: =_xlfn.XLOOKUP(B11,Talente!A:A,Talente!D:D) -> Intuition | F11: =_xlfn.XLOOKUP(E11,Eigenschaften!$B$20:$B$27,Eigenschaften!$H$20:$H$27,"NaN",1) -> 15 | G11: =_xlfn.XLOOKUP(B11,Talente!A:A,Talente!E:E) -> Gewandheit | H11: =_xlfn.XLOOKUP(G11,Eigenschaften!$B$20:$B$27,Eigenschaften!$H$20:$H$27,"NaN",1) -> 14 | I11: =C11&": "&D11&" | "&E11&": "&F11&" | "&G11&": "&H11 -> Mut: 13 | Intuition: 15 | Gewandheit: 14 | J11: =_xlfn.XLOOKUP(B11,Talente!A:A,Talente!F:F) -> C | K11: =_xlfn.XLOOKUP(B11,Talente!A:A,Talente!G:G) -> x1 | L11: =IF(NOT(ISERROR(FIND("x",K11))),RIGHT(K11,1)*$H$2,IF(K11<0,IF(($H$2+K11)>0,$H$2+K11,0),IF(K11="-",0,0))) -> 1 | M11: 7 | N11: =MAX(D11:H11)+3 -> 18 | O11: 0 | P11: =IF(M11="-","-",M11-L11+O11) -> 6
B12: Schwimmen | C12: =_xlfn.XLOOKUP(B12,Talente!A:A,Talente!C:C) -> Gewandheit | D12: =_xlfn.XLOOKUP(C12,Eigenschaften!$B$20:$B$27,Eigenschaften!$H$20:$H$27,"NaN",1) -> 14 | E12: =_xlfn.XLOOKUP(B12,Talente!A:A,Talente!D:D) -> Konstitution | F12: =_xlfn.XLOOKUP(E12,Eigenschaften!$B$20:$B$27,Eigenschaften!$H$20:$H$27,"NaN",1) -> 12 | G12: =_xlfn.XLOOKUP(B12,Talente!A:A,Talente!E:E) -> Körperkraft | H12: =_xlfn.XLOOKUP(G12,Eigenschaften!$B$20:$B$27,Eigenschaften!$H$20:$H$27,"NaN",1) -> 12 | I12: =C12&": "&D12&" | "&E12&": "&F12&" | "&G12&": "&H12 -> Gewandheit: 14 | Konstitution: 12 | Körperkraft: 12 | J12: =_xlfn.XLOOKUP(B12,Talente!A:A,Talente!F:F) -> D | K12: =_xlfn.XLOOKUP(B12,Talente!A:A,Talente!G:G) -> x2 | L12: =IF(NOT(ISERROR(FIND("x",K12))),RIGHT(K12,1)*$H$2,IF(K12<0,IF(($H$2+K12)>0,$H$2+K12,0),IF(K12="-",0,0))) -> 2 | M12: 1 | N12: =MAX(D12:H12)+3 -> 17 | O12: 0 | P12: =IF(M12="-","-",M12-L12+O12) -> -1 | U12: Spezielle Erfahrung
B13: Selbstbeherrschung | C13: =_xlfn.XLOOKUP(B13,Talente!A:A,Talente!C:C) -> Mut | D13: =_xlfn.XLOOKUP(C13,Eigenschaften!$B$20:$B$27,Eigenschaften!$H$20:$H$27,"NaN",1) -> 13 | E13: =_xlfn.XLOOKUP(B13,Talente!A:A,Talente!D:D) -> Konstitution | F13: =_xlfn.XLOOKUP(E13,Eigenschaften!$B$20:$B$27,Eigenschaften!$H$20:$H$27,"NaN",1) -> 12 | G13: =_xlfn.XLOOKUP(B13,Talente!A:A,Talente!E:E) -> Körperkraft | H13: =_xlfn.XLOOKUP(G13,Eigenschaften!$B$20:$B$27,Eigenschaften!$H$20:$H$27,"NaN",1) -> 12 | I13: =C13&": "&D13&" | "&E13&": "&F13&" | "&G13&": "&H13 -> Mut: 13 | Konstitution: 12 | Körperkraft: 12 | J13: =_xlfn.XLOOKUP(B13,Talente!A:A,Talente!F:F) -> D | K13: =_xlfn.XLOOKUP(B13,Talente!A:A,Talente!G:G) -> - | L13: =IF(NOT(ISERROR(FIND("x",K13))),RIGHT(K13,1)*$H$2,IF(K13<0,IF(($H$2+K13)>0,$H$2+K13,0),IF(K13="-",0,0))) -> 0 | M13: 4 | N13: =MAX(D13:H13)+3 -> 16 | O13: 0 | P13: =IF(M13="-","-",M13-L13+O13) -> 4
B14: Sich Verstecken | C14: =_xlfn.XLOOKUP(B14,Talente!A:A,Talente!C:C) -> Mut | D14: =_xlfn.XLOOKUP(C14,Eigenschaften!$B$20:$B$27,Eigenschaften!$H$20:$H$27,"NaN",1) -> 13 | E14: =_xlfn.XLOOKUP(B14,Talente!A:A,Talente!D:D) -> Intuition | F14: =_xlfn.XLOOKUP(E14,Eigenschaften!$B$20:$B$27,Eigenschaften!$H$20:$H$27,"NaN",1) -> 15 | G14: =_xlfn.XLOOKUP(B14,Talente!A:A,Talente!E:E) -> Gewandheit | H14: =_xlfn.XLOOKUP(G14,Eigenschaften!$B$20:$B$27,Eigenschaften!$H$20:$H$27,"NaN",1) -> 14 | I14: =C14&": "&D14&" | "&E14&": "&F14&" | "&G14&": "&H14 -> Mut: 13 | Intuition: 15 | Gewandheit: 14 | J14: =_xlfn.XLOOKUP(B14,Talente!A:A,Talente!F:F) -> C | K14: =_xlfn.XLOOKUP(B14,Talente!A:A,Talente!G:G) -> -2 | L14: =IF(NOT(ISERROR(FIND("x",K14))),RIGHT(K14,1)*$H$2,IF(K14<0,IF(($H$2+K14)>0,$H$2+K14,0),IF(K14="-",0,0))) -> 0 | M14: 7 | N14: =MAX(D14:H14)+3 -> 18 | O14: 0 | P14: =IF(M14="-","-",M14-L14+O14) -> 7
B15: Singen | C15: =_xlfn.XLOOKUP(B15,Talente!A:A,Talente!C:C) -> Intuition | D15: =_xlfn.XLOOKUP(C15,Eigenschaften!$B$20:$B$27,Eigenschaften!$H$20:$H$27,"NaN",1) -> 15 | E15: =_xlfn.XLOOKUP(B15,Talente!A:A,Talente!D:D) -> Charisma | F15: =_xlfn.XLOOKUP(E15,Eigenschaften!$B$20:$B$27,Eigenschaften!$H$20:$H$27,"NaN",1) -> 15 | G15: =_xlfn.XLOOKUP(B15,Talente!A:A,Talente!E:E) -> Charisma | H15: =_xlfn.XLOOKUP(G15,Eigenschaften!$B$20:$B$27,Eigenschaften!$H$20:$H$27,"NaN",1) -> 15 | I15: =C15&": "&D15&" | "&E15&": "&F15&" | "&G15&": "&H15 -> Intuition: 15 | Charisma: 15 | Charisma: 15 | J15: =_xlfn.XLOOKUP(B15,Talente!A:A,Talente!F:F) -> C | K15: =_xlfn.XLOOKUP(B15,Talente!A:A,Talente!G:G) -> -3 | L15: =IF(NOT(ISERROR(FIND("x",K15))),RIGHT(K15,1)*$H$2,IF(K15<0,IF(($H$2+K15)>0,$H$2+K15,0),IF(K15="-",0,0))) -> 0 | N15: =MAX(D15:H15)+3 -> 18 | O15: 0 | P15: =IF(M15="-","-",M15-L15+O15) -> 0
B16: Sinnesschärfe | C16: =_xlfn.XLOOKUP(B16,Talente!A:A,Talente!C:C) -> Klugheit | D16: =_xlfn.XLOOKUP(C16,Eigenschaften!$B$20:$B$27,Eigenschaften!$H$20:$H$27,"NaN",1) -> 12 | E16: =_xlfn.XLOOKUP(B16,Talente!A:A,Talente!D:D) -> Intuition | F16: =_xlfn.XLOOKUP(E16,Eigenschaften!$B$20:$B$27,Eigenschaften!$H$20:$H$27,"NaN",1) -> 15 | G16: =_xlfn.XLOOKUP(B16,Talente!A:A,Talente!E:E) -> Intuition | H16: =_xlfn.XLOOKUP(G16,Eigenschaften!$B$20:$B$27,Eigenschaften!$H$20:$H$27,"NaN",1) -> 15 | I16: =C16&": "&D16&" | "&E16&": "&F16&" | "&G16&": "&H16 -> Klugheit: 12 | Intuition: 15 | Intuition: 15 | J16: =_xlfn.XLOOKUP(B16,Talente!A:A,Talente!F:F) -> D | K16: =_xlfn.XLOOKUP(B16,Talente!A:A,Talente!G:G) -> spez. | L16: =IF(NOT(ISERROR(FIND("x",K16))),RIGHT(K16,1)*$H$2,IF(K16<0,IF(($H$2+K16)>0,$H$2+K16,0),IF(K16="-",0,0))) -> 0 | M16: 8 | N16: =MAX(D16:H16)+3 -> 18 | O16: 0 | P16: =IF(M16="-","-",M16-L16+O16) -> 8
B17: Skifahren | C17: =_xlfn.XLOOKUP(B17,Talente!A:A,Talente!C:C) -> Gewandheit | D17: =_xlfn.XLOOKUP(C17,Eigenschaften!$B$20:$B$27,Eigenschaften!$H$20:$H$27,"NaN",1) -> 14 | E17: =_xlfn.XLOOKUP(B17,Talente!A:A,Talente!D:D) -> Gewandheit | F17: =_xlfn.XLOOKUP(E17,Eigenschaften!$B$20:$B$27,Eigenschaften!$H$20:$H$27,"NaN",1) -> 14 | G17: =_xlfn.XLOOKUP(B17,Talente!A:A,Talente!E:E) -> Konstitution | H17: =_xlfn.XLOOKUP(G17,Eigenschaften!$B$20:$B$27,Eigenschaften!$H$20:$H$27,"NaN",1) -> 12 | I17: =C17&": "&D17&" | "&E17&": "&F17&" | "&G17&": "&H17 -> Gewandheit: 14 | Gewandheit: 14 | Konstitution: 12 | J17: =_xlfn.XLOOKUP(B17,Talente!A:A,Talente!F:F) -> B | K17: =_xlfn.XLOOKUP(B17,Talente!A:A,Talente!G:G) -> -2 | L17: =IF(NOT(ISERROR(FIND("x",K17))),RIGHT(K17,1)*$H$2,IF(K17<0,IF(($H$2+K17)>0,$H$2+K17,0),IF(K17="-",0,0))) -> 0 | N17: =MAX(D17:H17)+3 -> 17 | O17: 0 | P17: =IF(M17="-","-",M17-L17+O17) -> 0
B18: Stimmen Imitieren | C18: =_xlfn.XLOOKUP(B18,Talente!A:A,Talente!C:C) -> Klugheit | D18: =_xlfn.XLOOKUP(C18,Eigenschaften!$B$20:$B$27,Eigenschaften!$H$20:$H$27,"NaN",1) -> 12 | E18: =_xlfn.XLOOKUP(B18,Talente!A:A,Talente!D:D) -> Intuition | F18: =_xlfn.XLOOKUP(E18,Eigenschaften!$B$20:$B$27,Eigenschaften!$H$20:$H$27,"NaN",1) -> 15 | G18: =_xlfn.XLOOKUP(B18,Talente!A:A,Talente!E:E) -> Charisma | H18: =_xlfn.XLOOKUP(G18,Eigenschaften!$B$20:$B$27,Eigenschaften!$H$20:$H$27,"NaN",1) -> 15 | I18: =C18&": "&D18&" | "&E18&": "&F18&" | "&G18&": "&H18 -> Klugheit: 12 | Intuition: 15 | Charisma: 15 | J18: =_xlfn.XLOOKUP(B18,Talente!A:A,Talente!F:F) -> C | K18: =_xlfn.XLOOKUP(B18,Talente!A:A,Talente!G:G) -> -4 | L18: =IF(NOT(ISERROR(FIND("x",K18))),RIGHT(K18,1)*$H$2,IF(K18<0,IF(($H$2+K18)>0,$H$2+K18,0),IF(K18="-",0,0))) -> 0 | N18: =MAX(D18:H18)+3 -> 18 | O18: 0 | P18: =IF(M18="-","-",M18-L18+O18) -> 0
B19: Tanzen | C19: =_xlfn.XLOOKUP(B19,Talente!A:A,Talente!C:C) -> Charisma | D19: =_xlfn.XLOOKUP(C19,Eigenschaften!$B$20:$B$27,Eigenschaften!$H$20:$H$27,"NaN",1) -> 15 | E19: =_xlfn.XLOOKUP(B19,Talente!A:A,Talente!D:D) -> Gewandheit | F19: =_xlfn.XLOOKUP(E19,Eigenschaften!$B$20:$B$27,Eigenschaften!$H$20:$H$27,"NaN",1) -> 14 | G19: =_xlfn.XLOOKUP(B19,Talente!A:A,Talente!E:E) -> Gewandheit | H19: =_xlfn.XLOOKUP(G19,Eigenschaften!$B$20:$B$27,Eigenschaften!$H$20:$H$27,"NaN",1) -> 14 | I19: =C19&": "&D19&" | "&E19&": "&F19&" | "&G19&": "&H19 -> Charisma: 15 | Gewandheit: 14 | Gewandheit: 14 | J19: =_xlfn.XLOOKUP(B19,Talente!A:A,Talente!F:F) -> B | K19: =_xlfn.XLOOKUP(B19,Talente!A:A,Talente!G:G) -> x2 | L19: =IF(NOT(ISERROR(FIND("x",K19))),RIGHT(K19,1)*$H$2,IF(K19<0,IF(($H$2+K19)>0,$H$2+K19,0),IF(K19="-",0,0))) -> 2 | M19: 6 | N19: =MAX(D19:H19)+3 -> 18 | O19: 0 | P19: =IF(M19="-","-",M19-L19+O19) -> 4
B20: Taschendiebstahl | C20: =_xlfn.XLOOKUP(B20,Talente!A:A,Talente!C:C) -> Mut | D20: =_xlfn.XLOOKUP(C20,Eigenschaften!$B$20:$B$27,Eigenschaften!$H$20:$H$27,"NaN",1) -> 13 | E20: =_xlfn.XLOOKUP(B20,Talente!A:A,Talente!D:D) -> Intuition | F20: =_xlfn.XLOOKUP(E20,Eigenschaften!$B$20:$B$27,Eigenschaften!$H$20:$H$27,"NaN",1) -> 15 | G20: =_xlfn.XLOOKUP(B20,Talente!A:A,Talente!E:E) -> Fingerfertigkeit | H20: =_xlfn.XLOOKUP(G20,Eigenschaften!$B$20:$B$27,Eigenschaften!$H$20:$H$27,"NaN",1) -> 10 | I20: =C20&": "&D20&" | "&E20&": "&F20&" | "&G20&": "&H20 -> Mut: 13 | Intuition: 15 | Fingerfertigkeit: 10 | J20: =_xlfn.XLOOKUP(B20,Talente!A:A,Talente!F:F) -> C | K20: =_xlfn.XLOOKUP(B20,Talente!A:A,Talente!G:G) -> x2 | L20: =IF(NOT(ISERROR(FIND("x",K20))),RIGHT(K20,1)*$H$2,IF(K20<0,IF(($H$2+K20)>0,$H$2+K20,0),IF(K20="-",0,0))) -> 2 | N20: =MAX(D20:H20)+3 -> 18 | O20: 0 | P20: =IF(M20="-","-",M20-L20+O20) -> -2
B21: Zechen | C21: =_xlfn.XLOOKUP(B21,Talente!A:A,Talente!C:C) -> Intuition | D21: =_xlfn.XLOOKUP(C21,Eigenschaften!$B$20:$B$27,Eigenschaften!$H$20:$H$27,"NaN",1) -> 15 | E21: =_xlfn.XLOOKUP(B21,Talente!A:A,Talente!D:D) -> Konstitution | F21: =_xlfn.XLOOKUP(E21,Eigenschaften!$B$20:$B$27,Eigenschaften!$H$20:$H$27,"NaN",1) -> 12 | G21: =_xlfn.XLOOKUP(B21,Talente!A:A,Talente!E:E) -> Körperkraft | H21: =_xlfn.XLOOKUP(G21,Eigenschaften!$B$20:$B$27,Eigenschaften!$H$20:$H$27,"NaN",1) -> 12 | I21: =C21&": "&D21&" | "&E21&": "&F21&" | "&G21&": "&H21 -> Intuition: 15 | Konstitution: 12 | Körperkraft: 12 | J21: =_xlfn.XLOOKUP(B21,Talente!A:A,Talente!F:F) -> B | K21: =_xlfn.XLOOKUP(B21,Talente!A:A,Talente!G:G) -> - | L21: =IF(NOT(ISERROR(FIND("x",K21))),RIGHT(K21,1)*$H$2,IF(K21<0,IF(($H$2+K21)>0,$H$2+K21,0),IF(K21="-",0,0))) -> 0 | N21: =MAX(D21:H21)+3 -> 18 | O21: 0 | P21: =IF(M21="-","-",M21-L21+O21) -> 0
B23: Wissenstalente | C23: Eigenschaft 1 | D23: Eigenschaft 1 | E23: Eigenschaft 2 | F23: Eigenschaft 2 | G23: Eigenschaft 3 | H23: Eigenschaft 3 | I23: =I3 -> Eigenschaften | J23: =J3 -> Kompl. | K23: =K3 -> BE | L23: =L3 -> eBE | M23: =M3 -> TaW | N23: =N3 -> max. TaW | O23: =O3 -> Mod | P23: =P3 -> TaW | ... S23: =S3 -> Sonderfertigkeiten
B24: Anatomie | C24: =_xlfn.XLOOKUP(B24,Talente!A:A,Talente!C:C) -> Mut | D24: =_xlfn.XLOOKUP(C24,Eigenschaften!$B$20:$B$27,Eigenschaften!$H$20:$H$27,"NaN",1) -> 13 | E24: =_xlfn.XLOOKUP(B24,Talente!A:A,Talente!D:D) -> Klugheit | F24: =_xlfn.XLOOKUP(E24,Eigenschaften!$B$20:$B$27,Eigenschaften!$H$20:$H$27,"NaN",1) -> 12 | G24: =_xlfn.XLOOKUP(B24,Talente!A:A,Talente!E:E) -> Fingerfertigkeit | H24: =_xlfn.XLOOKUP(G24,Eigenschaften!$B$20:$B$27,Eigenschaften!$H$20:$H$27,"NaN",1) -> 10 | I24: =C24&": "&D24&" | "&E24&": "&F24&" | "&G24&": "&H24 -> Mut: 13 | Klugheit: 12 | Fingerfertigkeit: 10 | J24: =_xlfn.XLOOKUP(B24,Talente!A:A,Talente!F:F) -> B | K24: =_xlfn.XLOOKUP(B24,Talente!A:A,Talente!G:G) -> - | L24: =IF(NOT(ISERROR(FIND("x",K24))),RIGHT(K24,1)*$H$2,IF(K24<0,IF(($H$2+K24)>0,$H$2+K24,0),IF(K24="-",0,0))) -> 0 | M24: 4 | N24: =MAX(D24:H24)+3 -> 16 | O24: 0 | P24: =IF(M24="-","-",M24-L24+O24) -> 4
B25: Baukunst | C25: =_xlfn.XLOOKUP(B25,Talente!A:A,Talente!C:C) -> Klugheit | D25: =_xlfn.XLOOKUP(C25,Eigenschaften!$B$20:$B$27,Eigenschaften!$H$20:$H$27,"NaN",1) -> 12 | E25: =_xlfn.XLOOKUP(B25,Talente!A:A,Talente!D:D) -> Klugheit | F25: =_xlfn.XLOOKUP(E25,Eigenschaften!$B$20:$B$27,Eigenschaften!$H$20:$H$27,"NaN",1) -> 12 | G25: =_xlfn.XLOOKUP(B25,Talente!A:A,Talente!E:E) -> Fingerfertigkeit | H25: =_xlfn.XLOOKUP(G25,Eigenschaften!$B$20:$B$27,Eigenschaften!$H$20:$H$27,"NaN",1) -> 10 | I25: =C25&": "&D25&" | "&E25&": "&F25&" | "&G25&": "&H25 -> Klugheit: 12 | Klugheit: 12 | Fingerfertigkeit: 10 | J25: =_xlfn.XLOOKUP(B25,Talente!A:A,Talente!F:F) -> B | K25: =_xlfn.XLOOKUP(B25,Talente!A:A,Talente!G:G) -> - | L25: =IF(NOT(ISERROR(FIND("x",K25))),RIGHT(K25,1)*$H$2,IF(K25<0,IF(($H$2+K25)>0,$H$2+K25,0),IF(K25="-",0,0))) -> 0 | N25: =MAX(D25:H25)+3 -> 15 | O25: 0 | P25: =IF(M25="-","-",M25-L25+O25) -> 0
B26: Brett-/Kartenspiel | C26: =_xlfn.XLOOKUP(B26,Talente!A:A,Talente!C:C) -> Klugheit | D26: =_xlfn.XLOOKUP(C26,Eigenschaften!$B$20:$B$27,Eigenschaften!$H$20:$H$27,"NaN",1) -> 12 | E26: =_xlfn.XLOOKUP(B26,Talente!A:A,Talente!D:D) -> Klugheit | F26: =_xlfn.XLOOKUP(E26,Eigenschaften!$B$20:$B$27,Eigenschaften!$H$20:$H$27,"NaN",1) -> 12 | G26: =_xlfn.XLOOKUP(B26,Talente!A:A,Talente!E:E) -> Intuition | H26: =_xlfn.XLOOKUP(G26,Eigenschaften!$B$20:$B$27,Eigenschaften!$H$20:$H$27,"NaN",1) -> 15 | I26: =C26&": "&D26&" | "&E26&": "&F26&" | "&G26&": "&H26 -> Klugheit: 12 | Klugheit: 12 | Intuition: 15 | J26: =_xlfn.XLOOKUP(B26,Talente!A:A,Talente!F:F) -> B | K26: =_xlfn.XLOOKUP(B26,Talente!A:A,Talente!G:G) -> - | L26: =IF(NOT(ISERROR(FIND("x",K26))),RIGHT(K26,1)*$H$2,IF(K26<0,IF(($H$2+K26)>0,$H$2+K26,0),IF(K26="-",0,0))) -> 0 | N26: =MAX(D26:H26)+3 -> 18 | O26: 0 | P26: =IF(M26="-","-",M26-L26+O26) -> 0
B27: Geographie | C27: =_xlfn.XLOOKUP(B27,Talente!A:A,Talente!C:C) -> Klugheit | D27: =_xlfn.XLOOKUP(C27,Eigenschaften!$B$20:$B$27,Eigenschaften!$H$20:$H$27,"NaN",1) -> 12 | E27: =_xlfn.XLOOKUP(B27,Talente!A:A,Talente!D:D) -> Klugheit | F27: =_xlfn.XLOOKUP(E27,Eigenschaften!$B$20:$B$27,Eigenschaften!$H$20:$H$27,"NaN",1) -> 12 | G27: =_xlfn.XLOOKUP(B27,Talente!A:A,Talente!E:E) -> Intuition | H27: =_xlfn.XLOOKUP(G27,Eigenschaften!$B$20:$B$27,Eigenschaften!$H$20:$H$27,"NaN",1) -> 15 | I27: =C27&": "&D27&" | "&E27&": "&F27&" | "&G27&": "&H27 -> Klugheit: 12 | Klugheit: 12 | Intuition: 15 | J27: =_xlfn.XLOOKUP(B27,Talente!A:A,Talente!F:F) -> B | K27: =_xlfn.XLOOKUP(B27,Talente!A:A,Talente!G:G) -> - | L27: =IF(NOT(ISERROR(FIND("x",K27))),RIGHT(K27,1)*$H$2,IF(K27<0,IF(($H$2+K27)>0,$H$2+K27,0),IF(K27="-",0,0))) -> 0 | N27: =MAX(D27:H27)+3 -> 18 | O27: 0 | P27: =IF(M27="-","-",M27-L27+O27) -> 0
B28: Geschichtswissen | C28: =_xlfn.XLOOKUP(B28,Talente!A:A,Talente!C:C) -> Klugheit | D28: =_xlfn.XLOOKUP(C28,Eigenschaften!$B$20:$B$27,Eigenschaften!$H$20:$H$27,"NaN",1) -> 12 | E28: =_xlfn.XLOOKUP(B28,Talente!A:A,Talente!D:D) -> Klugheit | F28: =_xlfn.XLOOKUP(E28,Eigenschaften!$B$20:$B$27,Eigenschaften!$H$20:$H$27,"NaN",1) -> 12 | G28: =_xlfn.XLOOKUP(B28,Talente!A:A,Talente!E:E) -> Intuition | H28: =_xlfn.XLOOKUP(G28,Eigenschaften!$B$20:$B$27,Eigenschaften!$H$20:$H$27,"NaN",1) -> 15 | I28: =C28&": "&D28&" | "&E28&": "&F28&" | "&G28&": "&H28 -> Klugheit: 12 | Klugheit: 12 | Intuition: 15 | J28: =_xlfn.XLOOKUP(B28,Talente!A:A,Talente!F:F) -> B | K28: =_xlfn.XLOOKUP(B28,Talente!A:A,Talente!G:G) -> - | L28: =IF(NOT(ISERROR(FIND("x",K28))),RIGHT(K28,1)*$H$2,IF(K28<0,IF(($H$2+K28)>0,$H$2+K28,0),IF(K28="-",0,0))) -> 0 | N28: =MAX(D28:H28)+3 -> 18 | O28: 0 | P28: =IF(M28="-","-",M28-L28+O28) -> 0
B29: Gesteinskunde | C29: =_xlfn.XLOOKUP(B29,Talente!A:A,Talente!C:C) -> Klugheit | D29: =_xlfn.XLOOKUP(C29,Eigenschaften!$B$20:$B$27,Eigenschaften!$H$20:$H$27,"NaN",1) -> 12 | E29: =_xlfn.XLOOKUP(B29,Talente!A:A,Talente!D:D) -> Intuition | F29: =_xlfn.XLOOKUP(E29,Eigenschaften!$B$20:$B$27,Eigenschaften!$H$20:$H$27,"NaN",1) -> 15 | G29: =_xlfn.XLOOKUP(B29,Talente!A:A,Talente!E:E) -> Fingerfertigkeit | H29: =_xlfn.XLOOKUP(G29,Eigenschaften!$B$20:$B$27,Eigenschaften!$H$20:$H$27,"NaN",1) -> 10 | I29: =C29&": "&D29&" | "&E29&": "&F29&" | "&G29&": "&H29 -> Klugheit: 12 | Intuition: 15 | Fingerfertigkeit: 10 | J29: =_xlfn.XLOOKUP(B29,Talente!A:A,Talente!F:F) -> B | K29: =_xlfn.XLOOKUP(B29,Talente!A:A,Talente!G:G) -> - | L29: =IF(NOT(ISERROR(FIND("x",K29))),RIGHT(K29,1)*$H$2,IF(K29<0,IF(($H$2+K29)>0,$H$2+K29,0),IF(K29="-",0,0))) -> 0 | N29: =MAX(D29:H29)+3 -> 18 | O29: 0 | P29: =IF(M29="-","-",M29-L29+O29) -> 0
B30: Götter / Kulte | C30: =_xlfn.XLOOKUP(B30,Talente!A:A,Talente!C:C) -> Klugheit | D30: =_xlfn.XLOOKUP(C30,Eigenschaften!$B$20:$B$27,Eigenschaften!$H$20:$H$27,"NaN",1) -> 12 | E30: =_xlfn.XLOOKUP(B30,Talente!A:A,Talente!D:D) -> Klugheit | F30: =_xlfn.XLOOKUP(E30,Eigenschaften!$B$20:$B$27,Eigenschaften!$H$20:$H$27,"NaN",1) -> 12 | G30: =_xlfn.XLOOKUP(B30,Talente!A:A,Talente!E:E) -> Intuition | H30: =_xlfn.XLOOKUP(G30,Eigenschaften!$B$20:$B$27,Eigenschaften!$H$20:$H$27,"NaN",1) -> 15 | I30: =C30&": "&D30&" | "&E30&": "&F30&" | "&G30&": "&H30 -> Klugheit: 12 | Klugheit: 12 | Intuition: 15 | J30: =_xlfn.XLOOKUP(B30,Talente!A:A,Talente!F:F) -> B | K30: =_xlfn.XLOOKUP(B30,Talente!A:A,Talente!G:G) -> - | L30: =IF(NOT(ISERROR(FIND("x",K30))),RIGHT(K30,1)*$H$2,IF(K30<0,IF(($H$2+K30)>0,$H$2+K30,0),IF(K30="-",0,0))) -> 0 | M30: 6 | N30: =MAX(D30:H30)+3 -> 18 | O30: 0 | P30: =IF(M30="-","-",M30-L30+O30) -> 6
B31: Heraldik | C31: =_xlfn.XLOOKUP(B31,Talente!A:A,Talente!C:C) -> Klugheit | D31: =_xlfn.XLOOKUP(C31,Eigenschaften!$B$20:$B$27,Eigenschaften!$H$20:$H$27,"NaN",1) -> 12 | E31: =_xlfn.XLOOKUP(B31,Talente!A:A,Talente!D:D) -> Klugheit | F31: =_xlfn.XLOOKUP(E31,Eigenschaften!$B$20:$B$27,Eigenschaften!$H$20:$H$27,"NaN",1) -> 12 | G31: =_xlfn.XLOOKUP(B31,Talente!A:A,Talente!E:E) -> Fingerfertigkeit | H31: =_xlfn.XLOOKUP(G31,Eigenschaften!$B$20:$B$27,Eigenschaften!$H$20:$H$27,"NaN",1) -> 10 | I31: =C31&": "&D31&" | "&E31&": "&F31&" | "&G31&": "&H31 -> Klugheit: 12 | Klugheit: 12 | Fingerfertigkeit: 10 | J31: =_xlfn.XLOOKUP(B31,Talente!A:A,Talente!F:F) -> B | K31: =_xlfn.XLOOKUP(B31,Talente!A:A,Talente!G:G) -> - | L31: =IF(NOT(ISERROR(FIND("x",K31))),RIGHT(K31,1)*$H$2,IF(K31<0,IF(($H$2+K31)>0,$H$2+K31,0),IF(K31="-",0,0))) -> 0 | N31: =MAX(D31:H31)+3 -> 15 | O31: 0 | P31: =IF(M31="-","-",M31-L31+O31) -> 0
B32: Hüttenkunde | C32: =_xlfn.XLOOKUP(B32,Talente!A:A,Talente!C:C) -> Klugheit | D32: =_xlfn.XLOOKUP(C32,Eigenschaften!$B$20:$B$27,Eigenschaften!$H$20:$H$27,"NaN",1) -> 12 | E32: =_xlfn.XLOOKUP(B32,Talente!A:A,Talente!D:D) -> Intuition | F32: =_xlfn.XLOOKUP(E32,Eigenschaften!$B$20:$B$27,Eigenschaften!$H$20:$H$27,"NaN",1) -> 15 | G32: =_xlfn.XLOOKUP(B32,Talente!A:A,Talente!E:E) -> Konstitution | H32: =_xlfn.XLOOKUP(G32,Eigenschaften!$B$20:$B$27,Eigenschaften!$H$20:$H$27,"NaN",1) -> 12 | I32: =C32&": "&D32&" | "&E32&": "&F32&" | "&G32&": "&H32 -> Klugheit: 12 | Intuition: 15 | Konstitution: 12 | J32: =_xlfn.XLOOKUP(B32,Talente!A:A,Talente!F:F) -> B | K32: =_xlfn.XLOOKUP(B32,Talente!A:A,Talente!G:G) -> - | L32: =IF(NOT(ISERROR(FIND("x",K32))),RIGHT(K32,1)*$H$2,IF(K32<0,IF(($H$2+K32)>0,$H$2+K32,0),IF(K32="-",0,0))) -> 0 | N32: =MAX(D32:H32)+3 -> 18 | O32: 0 | P32: =IF(M32="-","-",M32-L32+O32) -> 0
B33: Kriegskunst | C33: =_xlfn.XLOOKUP(B33,Talente!A:A,Talente!C:C) -> Mut | D33: =_xlfn.XLOOKUP(C33,Eigenschaften!$B$20:$B$27,Eigenschaften!$H$20:$H$27,"NaN",1) -> 13 | E33: =_xlfn.XLOOKUP(B33,Talente!A:A,Talente!D:D) -> Klugheit | F33: =_xlfn.XLOOKUP(E33,Eigenschaften!$B$20:$B$27,Eigenschaften!$H$20:$H$27,"NaN",1) -> 12 | G33: =_xlfn.XLOOKUP(B33,Talente!A:A,Talente!E:E) -> Charisma | H33: =_xlfn.XLOOKUP(G33,Eigenschaften!$B$20:$B$27,Eigenschaften!$H$20:$H$27,"NaN",1) -> 15 | I33: =C33&": "&D33&" | "&E33&": "&F33&" | "&G33&": "&H33 -> Mut: 13 | Klugheit: 12 | Charisma: 15 | J33: =_xlfn.XLOOKUP(B33,Talente!A:A,Talente!F:F) -> B | K33: =_xlfn.XLOOKUP(B33,Talente!A:A,Talente!G:G) -> - | L33: =IF(NOT(ISERROR(FIND("x",K33))),RIGHT(K33,1)*$H$2,IF(K33<0,IF(($H$2+K33)>0,$H$2+K33,0),IF(K33="-",0,0))) -> 0 | N33: =MAX(D33:H33)+3 -> 18 | O33: 0 | P33: =IF(M33="-","-",M33-L33+O33) -> 0
B34: Kryptographie | C34: =_xlfn.XLOOKUP(B34,Talente!A:A,Talente!C:C) -> Klugheit | D34: =_xlfn.XLOOKUP(C34,Eigenschaften!$B$20:$B$27,Eigenschaften!$H$20:$H$27,"NaN",1) -> 12 | E34: =_xlfn.XLOOKUP(B34,Talente!A:A,Talente!D:D) -> Klugheit | F34: =_xlfn.XLOOKUP(E34,Eigenschaften!$B$20:$B$27,Eigenschaften!$H$20:$H$27,"NaN",1) -> 12 | G34: =_xlfn.XLOOKUP(B34,Talente!A:A,Talente!E:E) -> Intuition | H34: =_xlfn.XLOOKUP(G34,Eigenschaften!$B$20:$B$27,Eigenschaften!$H$20:$H$27,"NaN",1) -> 15 | I34: =C34&": "&D34&" | "&E34&": "&F34&" | "&G34&": "&H34 -> Klugheit: 12 | Klugheit: 12 | Intuition: 15 | J34: =_xlfn.XLOOKUP(B34,Talente!A:A,Talente!F:F) -> B | K34: =_xlfn.XLOOKUP(B34,Talente!A:A,Talente!G:G) -> - | L34: =IF(NOT(ISERROR(FIND("x",K34))),RIGHT(K34,1)*$H$2,IF(K34<0,IF(($H$2+K34)>0,$H$2+K34,0),IF(K34="-",0,0))) -> 0 | N34: =MAX(D34:H34)+3 -> 18 | O34: 0 | P34: =IF(M34="-","-",M34-L34+O34) -> 0
B35: Magiekunde | C35: =_xlfn.XLOOKUP(B35,Talente!A:A,Talente!C:C) -> Klugheit | D35: =_xlfn.XLOOKUP(C35,Eigenschaften!$B$20:$B$27,Eigenschaften!$H$20:$H$27,"NaN",1) -> 12 | E35: =_xlfn.XLOOKUP(B35,Talente!A:A,Talente!D:D) -> Klugheit | F35: =_xlfn.XLOOKUP(E35,Eigenschaften!$B$20:$B$27,Eigenschaften!$H$20:$H$27,"NaN",1) -> 12 | G35: =_xlfn.XLOOKUP(B35,Talente!A:A,Talente!E:E) -> Intuition | H35: =_xlfn.XLOOKUP(G35,Eigenschaften!$B$20:$B$27,Eigenschaften!$H$20:$H$27,"NaN",1) -> 15 | I35: =C35&": "&D35&" | "&E35&": "&F35&" | "&G35&": "&H35 -> Klugheit: 12 | Klugheit: 12 | Intuition: 15 | J35: =_xlfn.XLOOKUP(B35,Talente!A:A,Talente!F:F) -> B | K35: =_xlfn.XLOOKUP(B35,Talente!A:A,Talente!G:G) -> - | L35: =IF(NOT(ISERROR(FIND("x",K35))),RIGHT(K35,1)*$H$2,IF(K35<0,IF(($H$2+K35)>0,$H$2+K35,0),IF(K35="-",0,0))) -> 0 | M35: 6 | N35: =MAX(D35:H35)+3 -> 18 | O35: 0 | P35: =IF(M35="-","-",M35-L35+O35) -> 6
B36: Mechanik | C36: =_xlfn.XLOOKUP(B36,Talente!A:A,Talente!C:C) -> Klugheit | D36: =_xlfn.XLOOKUP(C36,Eigenschaften!$B$20:$B$27,Eigenschaften!$H$20:$H$27,"NaN",1) -> 12 | E36: =_xlfn.XLOOKUP(B36,Talente!A:A,Talente!D:D) -> Klugheit | F36: =_xlfn.XLOOKUP(E36,Eigenschaften!$B$20:$B$27,Eigenschaften!$H$20:$H$27,"NaN",1) -> 12 | G36: =_xlfn.XLOOKUP(B36,Talente!A:A,Talente!E:E) -> Fingerfertigkeit | H36: =_xlfn.XLOOKUP(G36,Eigenschaften!$B$20:$B$27,Eigenschaften!$H$20:$H$27,"NaN",1) -> 10 | I36: =C36&": "&D36&" | "&E36&": "&F36&" | "&G36&": "&H36 -> Klugheit: 12 | Klugheit: 12 | Fingerfertigkeit: 10 | J36: =_xlfn.XLOOKUP(B36,Talente!A:A,Talente!F:F) -> B | K36: =_xlfn.XLOOKUP(B36,Talente!A:A,Talente!G:G) -> - | L36: =IF(NOT(ISERROR(FIND("x",K36))),RIGHT(K36,1)*$H$2,IF(K36<0,IF(($H$2+K36)>0,$H$2+K36,0),IF(K36="-",0,0))) -> 0 | N36: =MAX(D36:H36)+3 -> 15 | O36: 0 | P36: =IF(M36="-","-",M36-L36+O36) -> 0
B37: Pflanzenkunde | C37: =_xlfn.XLOOKUP(B37,Talente!A:A,Talente!C:C) -> Klugheit | D37: =_xlfn.XLOOKUP(C37,Eigenschaften!$B$20:$B$27,Eigenschaften!$H$20:$H$27,"NaN",1) -> 12 | E37: =_xlfn.XLOOKUP(B37,Talente!A:A,Talente!D:D) -> Intuition | F37: =_xlfn.XLOOKUP(E37,Eigenschaften!$B$20:$B$27,Eigenschaften!$H$20:$H$27,"NaN",1) -> 15 | G37: =_xlfn.XLOOKUP(B37,Talente!A:A,Talente!E:E) -> Fingerfertigkeit | H37: =_xlfn.XLOOKUP(G37,Eigenschaften!$B$20:$B$27,Eigenschaften!$H$20:$H$27,"NaN",1) -> 10 | I37: =C37&": "&D37&" | "&E37&": "&F37&" | "&G37&": "&H37 -> Klugheit: 12 | Intuition: 15 | Fingerfertigkeit: 10 | J37: =_xlfn.XLOOKUP(B37,Talente!A:A,Talente!F:F) -> B | K37: =_xlfn.XLOOKUP(B37,Talente!A:A,Talente!G:G) -> - | L37: =IF(NOT(ISERROR(FIND("x",K37))),RIGHT(K37,1)*$H$2,IF(K37<0,IF(($H$2+K37)>0,$H$2+K37,0),IF(K37="-",0,0))) -> 0 | M37: 11 | N37: =MAX(D37:H37)+3 -> 18 | O37: 0 | P37: =IF(M37="-","-",M37-L37+O37) -> 11
B38: Philosophie | C38: =_xlfn.XLOOKUP(B38,Talente!A:A,Talente!C:C) -> Klugheit | D38: =_xlfn.XLOOKUP(C38,Eigenschaften!$B$20:$B$27,Eigenschaften!$H$20:$H$27,"NaN",1) -> 12 | E38: =_xlfn.XLOOKUP(B38,Talente!A:A,Talente!D:D) -> Klugheit | F38: =_xlfn.XLOOKUP(E38,Eigenschaften!$B$20:$B$27,Eigenschaften!$H$20:$H$27,"NaN",1) -> 12 | G38: =_xlfn.XLOOKUP(B38,Talente!A:A,Talente!E:E) -> Intuition | H38: =_xlfn.XLOOKUP(G38,Eigenschaften!$B$20:$B$27,Eigenschaften!$H$20:$H$27,"NaN",1) -> 15 | I38: =C38&": "&D38&" | "&E38&": "&F38&" | "&G38&": "&H38 -> Klugheit: 12 | Klugheit: 12 | Intuition: 15 | J38: =_xlfn.XLOOKUP(B38,Talente!A:A,Talente!F:F) -> B | K38: =_xlfn.XLOOKUP(B38,Talente!A:A,Talente!G:G) -> - | L38: =IF(NOT(ISERROR(FIND("x",K38))),RIGHT(K38,1)*$H$2,IF(K38<0,IF(($H$2+K38)>0,$H$2+K38,0),IF(K38="-",0,0))) -> 0 | M38: 2 | N38: =MAX(D38:H38)+3 -> 18 | O38: 0 | P38: =IF(M38="-","-",M38-L38+O38) -> 2
B39: Rechnen | C39: =_xlfn.XLOOKUP(B39,Talente!A:A,Talente!C:C) -> Klugheit | D39: =_xlfn.XLOOKUP(C39,Eigenschaften!$B$20:$B$27,Eigenschaften!$H$20:$H$27,"NaN",1) -> 12 | E39: =_xlfn.XLOOKUP(B39,Talente!A:A,Talente!D:D) -> Klugheit | F39: =_xlfn.XLOOKUP(E39,Eigenschaften!$B$20:$B$27,Eigenschaften!$H$20:$H$27,"NaN",1) -> 12 | G39: =_xlfn.XLOOKUP(B39,Talente!A:A,Talente!E:E) -> Intuition | H39: =_xlfn.XLOOKUP(G39,Eigenschaften!$B$20:$B$27,Eigenschaften!$H$20:$H$27,"NaN",1) -> 15 | I39: =C39&": "&D39&" | "&E39&": "&F39&" | "&G39&": "&H39 -> Klugheit: 12 | Klugheit: 12 | Intuition: 15 | J39: =_xlfn.XLOOKUP(B39,Talente!A:A,Talente!F:F) -> B | K39: =_xlfn.XLOOKUP(B39,Talente!A:A,Talente!G:G) -> - | L39: =IF(NOT(ISERROR(FIND("x",K39))),RIGHT(K39,1)*$H$2,IF(K39<0,IF(($H$2+K39)>0,$H$2+K39,0),IF(K39="-",0,0))) -> 0 | M39: 4 | N39: =MAX(D39:H39)+3 -> 18 | O39: 0 | P39: =IF(M39="-","-",M39-L39+O39) -> 4
B40: Rechtskunde | C40: =_xlfn.XLOOKUP(B40,Talente!A:A,Talente!C:C) -> Klugheit | D40: =_xlfn.XLOOKUP(C40,Eigenschaften!$B$20:$B$27,Eigenschaften!$H$20:$H$27,"NaN",1) -> 12 | E40: =_xlfn.XLOOKUP(B40,Talente!A:A,Talente!D:D) -> Klugheit | F40: =_xlfn.XLOOKUP(E40,Eigenschaften!$B$20:$B$27,Eigenschaften!$H$20:$H$27,"NaN",1) -> 12 | G40: =_xlfn.XLOOKUP(B40,Talente!A:A,Talente!E:E) -> Intuition | H40: =_xlfn.XLOOKUP(G40,Eigenschaften!$B$20:$B$27,Eigenschaften!$H$20:$H$27,"NaN",1) -> 15 | I40: =C40&": "&D40&" | "&E40&": "&F40&" | "&G40&": "&H40 -> Klugheit: 12 | Klugheit: 12 | Intuition: 15 | J40: =_xlfn.XLOOKUP(B40,Talente!A:A,Talente!F:F) -> B | K40: =_xlfn.XLOOKUP(B40,Talente!A:A,Talente!G:G) -> - | L40: =IF(NOT(ISERROR(FIND("x",K40))),RIGHT(K40,1)*$H$2,IF(K40<0,IF(($H$2+K40)>0,$H$2+K40,0),IF(K40="-",0,0))) -> 0 | N40: =MAX(D40:H40)+3 -> 18 | O40: 0 | P40: =IF(M40="-","-",M40-L40+O40) -> 0
B41: Sagen / Legenden | C41: =_xlfn.XLOOKUP(B41,Talente!A:A,Talente!C:C) -> Klugheit | D41: =_xlfn.XLOOKUP(C41,Eigenschaften!$B$20:$B$27,Eigenschaften!$H$20:$H$27,"NaN",1) -> 12 | E41: =_xlfn.XLOOKUP(B41,Talente!A:A,Talente!D:D) -> Intuition | F41: =_xlfn.XLOOKUP(E41,Eigenschaften!$B$20:$B$27,Eigenschaften!$H$20:$H$27,"NaN",1) -> 15 | G41: =_xlfn.XLOOKUP(B41,Talente!A:A,Talente!E:E) -> Charisma | H41: =_xlfn.XLOOKUP(G41,Eigenschaften!$B$20:$B$27,Eigenschaften!$H$20:$H$27,"NaN",1) -> 15 | I41: =C41&": "&D41&" | "&E41&": "&F41&" | "&G41&": "&H41 -> Klugheit: 12 | Intuition: 15 | Charisma: 15 | J41: =_xlfn.XLOOKUP(B41,Talente!A:A,Talente!F:F) -> B | K41: =_xlfn.XLOOKUP(B41,Talente!A:A,Talente!G:G) -> - | L41: =IF(NOT(ISERROR(FIND("x",K41))),RIGHT(K41,1)*$H$2,IF(K41<0,IF(($H$2+K41)>0,$H$2+K41,0),IF(K41="-",0,0))) -> 0 | M41: 6 | N41: =MAX(D41:H41)+3 -> 18 | O41: 0 | P41: =IF(M41="-","-",M41-L41+O41) -> 6
...

Sheet Magie
A1: Zaubername: | B1: Hauszauber | C1: Lernen nach | D1: Probe | E1: ZfW | F1: ZD | G1: Kosten | H1: Reichweite | I1: WD
A2: Harmlose Gestalt | B2: TRUE | C2: A | D2: KL/FF/KO | E2: 7 | F2: 10 | G2: 6 | H2: selbst | I2: ZfP* SR (A)
A3: Radau | B3: TRUE | C3: B | D3: MU/CH/KO | E3: 7 | F3: 4 | G3: 5 +1*KR | H3: 21 Schritt
A4: Schleier der Unwissenheit | B4: TRUE | C4: B | D4: KL/KL/FF | E4: 7 | F4: 1 SR | G4: 2+Mod | H4: selbst, Berührung | I4: ZfP* Stunden
A5: Spinnenlauf | B5: TRUE | C5: A | D5: IN/GE/KK | E5: 7 | F5: 10 | G5: 7+2*SR | H5: selbst, Berührung | I5: (A)
A6: Hexenholz | B6: TRUE | C6: B | D6: KL/FF/KK | E6: 5 | F6: 1 SR | G6: 5 + 1*SR | H6: 7 Schritt | I6: (A)
A7: Hexenknoten | B7: TRUE | C7: A | D7: KL/IN/CH | E7: 5 | F7: 10 | G7: 4 | I7: ZfP*/2 SR
A8: Große Gier | B8: FALSE | C8: B | D8: KL/KL/CH | E8: 4 | F8: 5 | G8: 6 | H8: Berührung | I8: ZfP* SR
A9: Tiere besprechen | B9: FALSE | C9: C | D9: MU/IN/CH | E9: 4 | F9: 50 | G9: Var. | H9: Berührung | I9: augenblicklich
A10: Adlerauge | B10: FALSE | C10: A | D10: KL/IN/FF | E10: 3 | F10: 5 | G10: 4 | H10: selbst | I10: 1 SR
A11: Armatrutz | B11: FALSE | C11: A | D11: IN/GE/KO | E11: 3 | F11: 3 | G11: RS*RS-ZfP*/2 (min. 4) | H11: Berührung | I11: 1 SR
A12: Blitz dich find | B12: FALSE | C12: A | D12: KL/IN/GE | E12: 3 | F12: 1 | G12: 4 | H12: ZfW Schritt | I12: ZfW/2 Aktionen
A13: Hexenkrallen | B13: TRUE | C13: A | D13: MU/IN/KO | E13: 3 | F13: 3 | G13: 3+1*SR | H13: selbst | I13: max. ZfP/2 SR
A14: Katzenaugen | B14: FALSE | C14: C | D14: KL/FF/KO | E14: 3 | F14: 10 | G14: 1 je 3 SR | H14: selbst | I14: (A)
A15: Krähenruf | B15: FALSE | C15: B | D15: MU/CH/CH | E15: 3 | F15: 7 | G15: 11 | H15: 21 Schritt | I15: max 20 KR
A16: Plumbarum schwerer Arm | B16: FALSE | C16: A | D16: CH/GE/KK | E16: 3 | F16: 3 | G16: 4+2 je Gegner | H16: 7 Schritt | I16: 5 KR
A17: Respondami Wahrheitszwang | B17: FALSE | C17: B | D17: MU/IN/CH | E17: 3 | F17: 3 | G17: 3 | H17: 1 Schritt | I17: 1 Frage
A18: Sensibar Empaticus | B18: FALSE | C18: C | D18: KL/IN/CH (+MR) | E18: 3 | F18: 10 | G18: 3 pro 10 Aktionen | H18: ZfW Schritt | I18: (A)
A19: Tiergedanken | B19: FALSE | C19: C | D19: MU/IN/CH | E19: 3 | F19: 20 | G19: 7*SR | H19: ZfW Schritt | I19: (A)
A20: Attributo | B20: FALSE | C20: A | D20: KL/CH/?? | E20: 2 | F20: 30 | G20: 7 | H20: Berührung | I20: 1 Stunde
A21: Hexenblick | B21: FALSE | C21: B | D21: IN/IN/CH | E21: 2 | F21: 4 | G21: 1 | H21: 3 Schritt | I21: 4 Aktionen
A22: Hexenspeichel | B22: FALSE | C22: C | D22: IN/CH/FF | E22: 2 | F22: 20 | G22: max. ZfW AsP | H22: Berührung | I22: augenblicklich
A23: Krötensprung | B23: FALSE | C23: A | D23: IN/GE/KK | E23: 2 | F23: 7 | G23: 3 | H23: selbst, Berührung | I23: augenblicklich
A24: Motoricus | B24: FALSE | C24: C | D24: KL/FF/KK | E24: 2 | F24: 5 | G24: 1 pro 5 Stein (min 3) | H24: 7 Schritt | I24: 1 SR (A)
A25: Zauberzwang | B25: FALSE | C25: D | D25: MU/CH/CH | E25: 2 | F25: 1 Stunde (3 SR) | G25: 27 | H25: Berührung
A26: Levthans Feuer | B26: FALSE | C26: C | D26: IN/CH/CH (+MR) | E26: 1 | F26: 7 | G26: 7 | H26: Berührung

Sheet Zauberliste
A1: Representation | B1: Hex
A2: Merkmale:
A3: Antimagie | B3: FALSE
A4: Beschwörung | B4: FALSE
A5: Eigenschaften | B5: TRUE
A6: Elementar | B6: FALSE
A7: Humus | B7: FALSE
A8: Feuer | B8: FALSE
A9: Erz | B9: FALSE
A10: Eis | B10: FALSE
A11: Luft | B11: FALSE
A12: Wasser | B12: FALSE
A13: Einfluss | B13: TRUE
A14: Form | B14: FALSE
... A29: Verständigung | B29: FALSE
V31: =_xlfn.XLOOKUP(V32,$A$3:$A$29,Zauberliste!$B$3:$B$29,"") -> FALSE | W31: =_xlfn.XLOOKUP(W32,$A$3:$A$29,Zauberliste!$B$3:$B$29,"") -> FALSE | X31: =_xlfn.XLOOKUP(X32,$A$3:$A$29,Zauberliste!$B$3:$B$29,"") -> TRUE | Y31: =_xlfn.XLOOKUP(Y32,$A$3:$A$29,Zauberliste!$B$3:$B$29,"") -> FALSE | Z31: =_xlfn.XLOOKUP(Z32,$A$3:$A$29,Zauberliste!$B$3:$B$29,"") -> FALSE | AA31: =_xlfn.XLOOKUP(AA32,$A$3:$A$29,Zauberliste!$B$3:$B$29,"") -> FALSE | AB31: =_xlfn.XLOOKUP(AB32,$A$3:$A$29,Zauberliste!$B$3:$B$29,"") -> FALSE | AC31: =_xlfn.XLOOKUP(AC32,$A$3:$A$29,Zauberliste!$B$3:$B$29,"") -> FALSE | ... AV31: =_xlfn.XLOOKUP(AV32,$A$3:$A$29,Zauberliste!$B$3:$B$29,"") -> FALSE
A32: Zaubername: | B32: Eigenschaften | C32: Aktiviert | D32: Hauszauber | E32: Lernbar | F32: Probe | G32: Lernkomplexität | H32: Merkmale | I32: Verfügbarkeit | J32: Lernkomplexität Zahl | K32: Lernen | L32: Eigenschaft 1 | M32: Spalte1 | N32: Eigenschaft 2 | O32: Spalte2 | P32: Eigenschaft 3 | Q32: Spalte3 | R32: Mod | S32: Überlauf Eigenschaften 1 | T32: Überlauf Eigenschaften 2 | U32: Überlauf Eigenschaften 3 | V32: Antimagie | W32: Beschwörung | X32: Eigenschaften | Y32: Elementar | Z32: Humus | AA32: Feuer | AB32: Erz | AC32: Eis | AD32: Luft | AE32: Wasser | AF32: Einfluss | AG32: Form | AH32: Geisterwesen | AI32: Heilung | AJ32: Hellsicht | AK32: Herbeirufung | AL32: Herrschaft | AM32: Illusion | AN32: Kraft | AO32: Limbus | AP32: Metamagie | AQ32: Objekt | AR32: Schaden | AS32: Telekinese | AT32: Temporal | AU32: Umwelt | AV32: Verständigung | AW32: ZfW | AX32: ZD | AY32: Kosten | AZ32: Reichweite | BA32: WD | BB32: Modifikationen
A33: Abvenenum reine Speise | B33: =L33&": "&M33&" | "&N33&": "&O33&" | "&P33&": "&Q33 -> Klugheit: 12 | Klugheit: 12 | Fingerfertigkeit: 10 | C33: FALSE | D33: FALSE | E33: =ISNUMBER(FIND($B$1,I33)) -> TRUE | F33: KL/KL/FF | G33: C | H33: Objekt | I33: Dru6, Elf6, Hex6, Mag6, Geo5, Ach4, Sch4 | J33: =_xlfn.XLOOKUP(G33,Rechner!$A$17:$A$25,Rechner!$B$17:$B$25) -> 4 | K33: =_xlfn.XLOOKUP(J33-SUMIF($V$31:$AV$31,TRUE,V33:AV33)-IF(D33=TRUE,1,0),Rechner!$B$17:$B$25,Rechner!$A$17:$A$25,"A+") -> C | L33: =_xlfn.XLOOKUP(S33,Eigenschaften!$C$20:$C$27,Eigenschaften!$B$20:$B$27) -> Klugheit | M33: =_xlfn.XLOOKUP(L33,Eigenschaften!$B$20:$B$27,Eigenschaften!$H$20:$H$27,"NaN",1) -> 12 | N33: =_xlfn.XLOOKUP(T33,Eigenschaften!$C$20:$C$27,Eigenschaften!$B$20:$B$27) -> Klugheit | O33: =_xlfn.XLOOKUP(N33,Eigenschaften!$B$20:$B$27,Eigenschaften!$H$20:$H$27,"NaN",1) -> 12 | P33: =_xlfn.XLOOKUP(U33,Eigenschaften!$C$20:$C$27,Eigenschaften!$B$20:$B$27) -> Fingerfertigkeit | Q33: =_xlfn.XLOOKUP(P33,Eigenschaften!$B$20:$B$27,Eigenschaften!$H$20:$H$27,"NaN",1) -> 10 | S33: {=_xlfn.TEXTSPLIT(F33,"/",,,,3)} -> KL | T33: KL | U33: FF | V33: =IF(ISNUMBER(SEARCH(V$32,$H33)),1,0) -> 0 | W33: =IF(ISNUMBER(SEARCH(W$32,$H33)),1,0) -> 0 | X33: =IF(ISNUMBER(SEARCH(X$32,$H33)),1,0) -> 0 | Y33: =IF(ISNUMBER(SEARCH(Y$32,$H33)),1,0) -> 0 | Z33: =IF(ISNUMBER(SEARCH(Z$32,$H33)),1,0) -> 0 | AA33: =IF(ISNUMBER(SEARCH(AA$32,$H33)),1,0) -> 0 | AB33: =IF(ISNUMBER(SEARCH(AB$32,$H33)),1,0) -> 0 | AC33: =IF(ISNUMBER(SEARCH(AC$32,$H33)),1,0) -> 0 | ... AV33: =IF(ISNUMBER(SEARCH(AV$32,$H33)),1,0) -> 0
