Workbook

Sheet Waffen
A1: Typ | B1: Waffe | C1: Talent | D1: Mögliche Manöver | E1: Aktivierte Manöver | F1: Komplexität
A2: Nahkampf | B2: Anderthalbhänder | C2: Anderthalbhänder | D2: Ausfall, Befreiungsschlag, Betäubungsschlag, Binden, Seitenwechsel, Offensiver Distanzklassenwechsel, Defensiver Kampfstil, Offensiver Kampfstil, Entwaffnen, Finte, Gegenhalten, Gezielter Stich (nur bei Kenntnis von halbschwert), Halbschwert, Hammerschlag, Klingensturm, Klingenwand, Meisterparade, Niederwerfen, Stumpfer Schlag, Sturmangriff, Windmühle, Wuchtschlag, | E2: Finte | F2: E
A3: Nahkampf | B3: Bastardschwert | C3: Anderthalbhänder | D3: Ausfall, Befreiungsschlag, Betäubungsschlag, Binden, Seitenwechsel, Offensiver Distanzklassenwechsel, Defensiver Kampfstil, Offensiver Kampfstil, Entwaffnen, Finte, Gegenhalten, Gezielter Stich (nur bei Kenntnis von halbschwert), Halbschwert, Hammerschlag, Klingensturm, Klingenwand, Meisterparade, Niederwerfen, Stumpfer Schlag, Sturmangriff, Windmühle, Wuchtschlag, | E3: Finte | F3: E
A4: Nahkampf | B4: Rondrakamm | C4: Anderthalbhänder | D4: Ausfall, Befreiungsschlag, Betäubungsschlag, Binden, Seitenwechsel, Offensiver Distanzklassenwechsel, Defensiver Kampfstil, Offensiver Kampfstil, Entwaffnen, Finte, Gegenhalten, Gezielter Stich (nur bei Kenntnis von halbschwert), Halbschwert, Hammerschlag, Klingensturm, Klingenwand, Meisterparade, Niederwerfen, Stumpfer Schlag, Sturmangriff, Windmühle, Wuchtschlag, | E4: Finte | F4: E
A5: Nahkampf | B5: Nachtwind | C5: Anderthalbhänder | D5: Ausfall, Befreiungsschlag, Betäubungsschlag, Binden, Seitenwechsel, Offensiver Distanzklassenwechsel, Defensiver Kampfstil, Offensiver Kampfstil, Entwaffnen, Finte, Gegenhalten, Gezielter Stich (nur bei Kenntnis von halbschwert), Halbschwert, Klingensturm, Klingenwand, Meisterparade, Niederwerfen, Stumpfer Schlag, Sturmangriff, Windmühle, Wuchtschlag, | E5: Finte | F5: E
A6: Nahkampf | B6: Tuzakmesser | C6: Anderthalbhänder | D6: Ausfall, Befreiungsschlag, Betäubungsschlag, Binden, Seitenwechsel, Offensiver Distanzklassenwechsel, Defensiver Kampfstil, Offensiver Kampfstil, Entwaffnen, Finte, Gegenhalten, Gezielter Stich (nur bei Kenntnis von halbschwert), Halbschwert, Hammerschlag, Klingensturm, Klingenwand, Meisterparade, Niederwerfen, Stumpfer Schlag, Sturmangriff, Windmühle, Wuchtschlag, | E6: Finte | F6: E
A7: Nahkampf | B7: Basiliskenzunge | C7: Dolche | D7: Ausfall, Binden, Seitenwechsel, Offensiver Distanzklassenwechsel, Defensiver Kampfstil, Offensiver Kampfstil, Doppelangriff, Entwaffnen aus der Attacke, Finte, Gegenhalten, Gezielter Stich, Klingensturm, Klingenwand, Meisterparade, Todesstoß, | E7: Finte | F7: D
A8: Nahkampf | B8: Borndorn | C8: Dolche | D8: Ausfall, Binden, Seitenwechsel, Offensiver Distanzklassenwechsel, Defensiver Kampfstil, Offensiver Kampfstil, Doppelangriff, Entwaffnen aus der Attacke, Finte, Gegenhalten, Gezielter Stich, Klingensturm, Klingenwand, Meisterparade, Todesstoß, | E8: Finte | F8: D
A9: Nahkampf | B9: Eberfänger | C9: Dolche | D9: Ausfall, Binden, Seitenwechsel, Offensiver Distanzklassenwechsel, Defensiver Kampfstil, Offensiver Kampfstil, Doppelangriff, Entwaffnen aus der Attacke, Finte, Gegenhalten, Gezielter Stich, Klingensturm, Klingenwand, Meisterparade, Todesstoß, | E9: Finte | F9: D
A10: Nahkampf | B10: Kurzschwert | C10: Dolche | D10: Ausfall, Binden, Seitenwechsel, Offensiver Distanzklassenwechsel, Defensiver Kampfstil, Offensiver Kampfstil, Doppelangriff, Entwaffnen aus der Attacke, Finte, Gegenhalten, Gezielter Stich, Klingensturm, Klingenwand, Meisterparade, Todesstoß, | E10: Finte | F10: D
A11: Nahkampf | B11: Ogerfänger | C11: Dolche | D11: Ausfall, Binden, Seitenwechsel, Offensiver Distanzklassenwechsel, Defensiver Kampfstil, Offensiver Kampfstil, Doppelangriff, Entwaffnen aus der Attacke, Finte, Gegenhalten, Gezielter Stich, Klingensturm, Klingenwand, Meisterparade, Todesstoß, | E11: Finte | F11: D
A12: Nahkampf | B12: improvisiert: Wurfdolch, | C12: Dolche | D12: Ausfall, Binden, Seitenwechsel, Offensiver Distanzklassenwechsel, Defensiver Kampfstil, Offensiver Kampfstil, Doppelangriff, Entwaffnen aus der Attacke, Finte, Gegenhalten, Gezielter Stich, Klingensturm, Klingenwand, Meisterparade, Todesstoß, | E12: Finte | F12: D
... A73: Nahkampf | B73: Kettenstab | C73: Kettenstäbe | D73: Ausfall, Befreiungsschlag, Betäubungsschlag, Binden, Seitenwechsel, Offensiver Distanzklassenwechsel, Defensiver Kampfstil, Offensiver Kampfstil, Entwaffnen, Finte, Gegenhalten, Klingensturm, Klingenwand, Meisterparade, Niederwerfen, Stumpfer Schlag, Sturmangriff, Windmühle, Wuchtschlag, | E73: Finte | F73: E
A74: Nahkampf | B74: Geißel | C74: Kettenwaffen | D74: Befreiungsschlag, Hammerschlag, Niederwerfen, Schildspalter, Sturmangriff, Windmühle, Wuchtschlag, | F74: D
A75: Nahkampf | B75: Kettenkugel | C75: Kettenwaffen | D75: Befreiungsschlag, Hammerschlag, Niederwerfen, Schildspalter, Sturmangriff, Windmühle, Wuchtschlag, | F75: D
A76: Nahkampf | B76: Morgenstern | C76: Kettenwaffen | D76: Befreiungsschlag, Hammerschlag, Niederwerfen, Schildspalter, Sturmangriff, Windmühle, Wuchtschlag, | F76: D
A77: Nahkampf | B77: Neunschwänzige | C77: Kettenwaffen | D77: Befreiungsschlag, Hammerschlag, Niederwerfen, Schildspalter, Sturmangriff, Windmühle, Wuchtschlag, | F77: D
A78: Nahkampf | B78: Ochsenherde | C78: Kettenwaffen | D78: Befreiungsschlag, Hammerschlag, Niederwerfen, Schildspalter, Sturmangriff, Windmühle, Wuchtschlag, | F78: D
A79: Nahkampf | B79: Ogerschelle | C79: Kettenwaffen | D79: Befreiungsschlag, Hammerschlag, Niederwerfen, Schildspalter, Sturmangriff, Windmühle, Wuchtschlag, | F79: D
A80: Nahkampf | B80: Dschadra | C80: Lanzenreiten | D80: angesagter Lanzenangriff, | F80: E
A81: Nahkampf | B81: Kriegslanze | C81: Lanzenreiten | D81: angesagter Lanzenangriff, | F81: E
A82: Nahkampf | B82: Turnierlanze | C82: Lanzenreiten | D82: angesagter Lanzenangriff, | F82: E
A83: Nahkampf | B83: Peitsche | C83: Peitsche | D83: Entwaffnen, Umreißen, | F83: E
A84: Nahkampf | B84: Säbel | C84: Säbel | D84: Ausfall, Befreiungsschlag, Betäubungsschlag, Binden, Seitenwechsel, Offensiver Distanzklassenwechsel, Defensiver Kampfstil, Offensiver Kampfstil, Doppelangriff, Entwaffnen, Entwaffnen (Meisterlich), Finte, Gegenhalten, Klingensturm, Klingenwand, Meisterparade, Stumpfer Schlag, Sturmangriff, Windmühle, Wuchtschlag, | E84: Finte | F84: D
A85: Nahkampf | B85: Amazonensäbel | C85: Säbel | D85: Ausfall, Befreiungsschlag, Betäubungsschlag, Binden, Seitenwechsel, Offensiver Distanzklassenwechsel, Defensiver Kampfstil, Offensiver Kampfstil, Doppelangriff, Entwaffnen, Entwaffnen (Meisterlich), Entwaffnen (Meisterlich), Finte, Gegenhalten, Klingensturm, Klingenwand, Meisterparade, Stumpfer Schlag, Sturmangriff, Windmühle, Wuchtschlag, | E85: Finte | F85: D
A86: Nahkampf | B86: Arbach | C86: Säbel | D86: Ausfall, Befreiungsschlag, Betäubungsschlag, Binden, Seitenwechsel, Offensiver Distanzklassenwechsel, Defensiver Kampfstil, Offensiver Kampfstil, Doppelangriff, Entwaffnen, Entwaffnen (Meisterlich), Finte, Gegenhalten, Klingensturm, Klingenwand, Meisterparade, Niederwerfen, Stumpfer Schlag, Sturmangriff, Windmühle, Wuchtschlag, | E86: Finte | F86: D
A87: Nahkampf | B87: Entermesser | C87: Säbel | D87: Ausfall, Befreiungsschlag, Betäubungsschlag, Binden, Seitenwechsel, Offensiver Distanzklassenwechsel, Defensiver Kampfstil, Offensiver Kampfstil, Doppelangriff, Entwaffnen, Entwaffnen (Meisterlich), Finte, Gegenhalten, Klingensturm, Klingenwand, Meisterparade, Stumpfer Schlag, Sturmangriff, Windmühle, Wuchtschlag, | E87: Finte | F87: D
A88: Nahkampf | B88: Haumesser | C88: Säbel | D88: Ausfall, Befreiungsschlag, Betäubungsschlag, Binden, Seitenwechsel, Offensiver Distanzklassenwechsel, Defensiver Kampfstil, Offensiver Kampfstil, Doppelangriff, Entwaffnen, Entwaffnen (Meisterlich), Finte, Gegenhalten, Klingensturm, Klingenwand, Meisterparade, Niederwerfen, Stumpfer Schlag, Sturmangriff, Windmühle, Wuchtschlag, | E88: Finte | F88: D
A89: Nahkampf | B89: Khunchomer | C89: Säbel | D89: Ausfall, Befreiungsschlag, Betäubungsschlag, Binden, Seitenwechsel, Offensiver Distanzklassenwechsel, Defensiver Kampfstil, Offensiver Kampfstil, Doppelangriff, Entwaffnen, Entwaffnen (Meisterlich), Finte, Gegenhalten, Klingensturm, Klingenwand, Meisterparade, Niederwerfen, Stumpfer Schlag, Sturmangriff, Windmühle, Wuchtschlag, | E89: Finte | F89: D
A90: Nahkampf | B90: Kurzschwert | C90: Säbel | D90: Ausfall, Befreiungsschlag, Betäubungsschlag, Binden, Seitenwechsel, Offensiver Distanzklassenwechsel, Defensiver Kampfstil, Offensiver Kampfstil, Doppelangriff, Entwaffnen, Entwaffnen (Meisterlich), Finte, Gegenhalten, Klingensturm, Klingenwand, Meisterparade, Stumpfer Schlag, Sturmangriff, Windmühle, Wuchtschlag, | E90: Finte | F90: D
A91: Nahkampf | B91: Kuslikersäbel | C91: Säbel | D91: Ausfall, Befreiungsschlag, Betäubungsschlag, Binden, Seitenwechsel, Offensiver Distanzklassenwechsel, Defensiver Kampfstil, Offensiver Kampfstil, Doppelangriff, Entwaffnen, Entwaffnen (Meisterlich), Finte, Gegenhalten, Klingensturm, Klingenwand, Meisterparade, Stumpfer Schlag, Sturmangriff, Windmühle, Wuchtschlag, | E91: Finte | F91: D
A92: Nahkampf | B92: Robbentöter | C92: Säbel | D92: Ausfall, Befreiungsschlag, Betäubungsschlag, Binden, Seitenwechsel, Offensiver Distanzklassenwechsel, Defensiver Kampfstil, Offensiver Kampfstil, Doppelangriff, Entwaffnen, Entwaffnen (Meisterlich), Finte, Gegenhalten, Klingensturm, Klingenwand, Meisterparade, Stumpfer Schlag, Sturmangriff, Windmühle, Wuchtschlag, | E92: Finte | F92: D
A93: Nahkampf | B93: Säbel | C93: Säbel | D93: Ausfall, Befreiungsschlag, Betäubungsschlag, Binden, Seitenwechsel, Offensiver Distanzklassenwechsel, Defensiver Kampfstil, Offensiver Kampfstil, Doppelangriff, Entwaffnen, Entwaffnen (Meisterlich), Finte, Gegenhalten, Klingensturm, Klingenwand, Meisterparade, Stumpfer Schlag, Sturmangriff, Windmühle, Wuchtschlag, | E93: Finte | F93: D
A94: Nahkampf | B94: Sklaventod | C94: Säbel | D94: Ausfall, Befreiungsschlag, Betäubungsschlag, Binden, Seitenwechsel, Offensiver Distanzklassenwechsel, Defensiver Kampfstil, Offensiver Kampfstil, Doppelangriff, Entwaffnen, Entwaffnen (Meisterlich), Finte, Gegenhalten, Klingensturm, Klingenwand, Meisterparade, Niederwerfen, Stumpfer Schlag, Sturmangriff, Windmühle, Wuchtschlag, | E94: Finte | F94: D
A95: Nahkampf | B95: Waqqif | C95: Säbel | D95: Ausfall, Befreiungsschlag, Betäubungsschlag, Binden, Seitenwechsel, Offensiver Distanzklassenwechsel, Defensiver Kampfstil, Offensiver Kampfstil, Doppelangriff, Entwaffnen, Entwaffnen (Meisterlich), Finte, Gegenhalten, Klingensturm, Klingenwand, Meisterparade, Stumpfer Schlag, Sturmangriff, Windmühle, Wuchtschlag, | E95: Finte | F95: D
... A128: Nahkampf | B128: Magierstab | C128: Stäbe | D128: Ausfall, Befreiungsschlag, Betäubungsschlag, Binden, Seitenwechsel, Offensiver Distanzklassenwechsel, Defensiver Kampfstil, Offensiver Kampfstil, Entwaffnen, Finte, Gegenhalten, Halbschwert, Klingensturm, Klingenwand, Meisterparade, Niederwerfen, Stumpfer Schlag, Sturmangriff, Umreißen, Windmühle, Wuchtschlag, | E128: Finte | F128: D
A129: Nahkampf | B129: Kriegsflegel | C129: Zweihandflegel | D129: Befreiungsschlag, Hammerschlag, Niederwerfen, Schildspalter, Sturmangriff, Windmühle, Wuchtschlag, | F129: D
A130: Nahkampf | B130: improvisiert: Dreschflegel | C130: Zweihandflegel | D130: Befreiungsschlag, Hammerschlag, Niederwerfen, Schildspalter, Sturmangriff, Windmühle, Wuchtschlag, | F130: D
A131: Nahkampf | B131: Barbarenstreitaxt | C131: Zweihand_Hiebwaffen | D131: Befreiungsschlag, Defensiver Kampfstil, Offensiver Kampfstil, Gegenhalten, Hammerschlag, Meisterparade, Niederwerfen, Schildspalter, Sturmangriff, Windmühle, Wuchtschlag, | F131: D
A132: Nahkampf | B132: EchsischeAxt | C132: Zweihand_Hiebwaffen | D132: Befreiungsschlag, Defensiver Kampfstil, Offensiver Kampfstil, Gegenhalten, Hammerschlag, Meisterparade, Niederwerfen, Schildspalter, Sturmangriff, Windmühle, Wuchtschlag, | F132: D
...

Sheet Kampftalente
A1: Typ | B1: Nahkampf | C1: Waffengattung | D1: Ersatzweise | E1: Komp. | F1: BE
A2: Nahkampf | B2: Anderthalbhänder | C2: {=_xlfn.TEXTJOIN(", ",,_xlfn._xlws.FILTER(Tabelle2[Waffe],Tabelle2[Talent]=Kampftalente!B2))} -> Anderthalbhänder, Bastardschwert, Rondrakamm, Nachtwind, Tuzakmesser | D2: Schwerter, Zweihandschwerter,Zweihandsäbel | E2: E | F2: -2
A3: Nahkampf | B3: Dolche | C3: {=_xlfn.TEXTJOIN(", ",,_xlfn._xlws.FILTER(Tabelle2[Waffe],Tabelle2[Talent]=Kampftalente!B3))} -> Basiliskenzunge, Borndorn, Eberfänger, Kurzschwert, Ogerfänger, improvisiert: Wurfdolch,, Wurfmesser, Dolch, Drachenzahn, Hakendolch, Jagdmesser, Langdolch, Linkhand, Mengbilar, Scheibendolch, Schwerer Dolch, Waqqif, Vulkanglasdolch, diverse Ess- und Arbeitsmesser | E3: D | F3: -1
A4: Nahkampf | B4: Fechtwaffen | C4: {=_xlfn.TEXTJOIN(", ",,_xlfn._xlws.FILTER(Tabelle2[Waffe],Tabelle2[Talent]=Kampftalente!B4))} -> Degen, Florett, Rapier, Wolfsmesser, Langdolch, Magierdegen, Panzerstecher, Robbentöter, Stockdegen | E4: E | F4: -1
A5: Nahkampf | B5: Hiebwaffen | C5: {=_xlfn.TEXTJOIN(", ",,_xlfn._xlws.FILTER(Tabelle2[Waffe],Tabelle2[Talent]=Kampftalente!B5))} -> Brabakbengel, Byakka, Gruufhai, Keule, Kriegsfächer, Lindwurmschläger, Molokdeschnaja, Orknase, Rabenschnabel, Schmiedehammer, Schneidzahn, Skraja, Sonnenszepter, Streitaxt, Streitkolben, Zwergenskraja, Beil, Fackel, Fleischerbeil, Knüppel, Sichel, Stuhlbein, Wurfbeil, Wurfkeule, improvisiert: Ast | E5: D | F5: -4
A6: Nahkampf | B6: Infanteriewaffen | C6: {=_xlfn.TEXTJOIN(", ",,_xlfn._xlws.FILTER(Tabelle2[Waffe],Tabelle2[Talent]=Kampftalente!B6))} -> Glefe, Hakenspieß, Hellebarde, Korspieß, Langaxt, Pailos, Partisane, Schnitter, Sturmsense, Warunkerhammer, Wurmspieß, improvisiert: Sense | E6: D | F6: -3
A7: Nahkampf | B7: Kettenstäbe | C7: {=_xlfn.TEXTJOIN(", ",,_xlfn._xlws.FILTER(Tabelle2[Waffe],Tabelle2[Talent]=Kampftalente!B7))} -> Dreigliederstab, Kettenstab | E7: E | F7: -1
A8: Nahkampf | B8: Kettenwaffen | C8: {=_xlfn.TEXTJOIN(", ",,_xlfn._xlws.FILTER(Tabelle2[Waffe],Tabelle2[Talent]=Kampftalente!B8))} -> Geißel, Kettenkugel, Morgenstern, Neunschwänzige, Ochsenherde, Ogerschelle | E8: D | F8: -3
A9: Nahkampf | B9: Lanzenreiten | C9: {=_xlfn.TEXTJOIN(", ",,_xlfn._xlws.FILTER(Tabelle2[Waffe],Tabelle2[Talent]=Kampftalente!B9))} -> Dschadra, Kriegslanze, Turnierlanze | E9: E | F9: -
A10: Nahkampf | B10: Raufen | C10: {=_xlfn.TEXTJOIN(", ",,_xlfn._xlws.FILTER(Tabelle2[Waffe],Tabelle2[Talent]=Kampftalente!B10))} -> Hände | E10: C | F10: 0
A11: Nahkampf | B11: Ringen | C11: {=_xlfn.TEXTJOIN(", ",,_xlfn._xlws.FILTER(Tabelle2[Waffe],Tabelle2[Talent]=Kampftalente!B11))} -> Hände | E11: D | F11: 0
A12: Nahkampf | B12: Säbel | C12: {=_xlfn.TEXTJOIN(", ",,_xlfn._xlws.FILTER(Tabelle2[Waffe],Tabelle2[Talent]=Kampftalente!B12))} -> Säbel, Amazonensäbel, Arbach, Entermesser, Haumesser, Khunchomer, Kurzschwert, Kuslikersäbel, Robbentöter, Säbel, Sklaventod, Waqqif, Wolfsmesser | E12: D | F12: -2
A13: Nahkampf | B13: Schwerter | C13: {=_xlfn.TEXTJOIN(", ",,_xlfn._xlws.FILTER(Tabelle2[Waffe],Tabelle2[Talent]=Kampftalente!B13))} -> Amazonensäbel, Arbach, Barbarenschwert, Bastardschwert, Breitschwert, Kurzschwert, Kuslikersäbel, Langschwert, Nachtwind, Rapier, Robbentöter, Säbel, Turnierschwert, Wolfsmesser | E13: E | F13: -2
A14: Nahkampf | B14: Speere | C14: {=_xlfn.TEXTJOIN(", ",,_xlfn._xlws.FILTER(Tabelle2[Waffe],Tabelle2[Talent]=Kampftalente!B14))} -> Drachentöter (zweihändig), Dreizack (einhändig), Dschadra (einhändig), Efferdbart (ein-/zweihändig), Holzspeer (einhändig), Jagdspieß( zweihändig), Partisane (zweihändig), Pike (zweihändig), Schnitter (ein-/zweihändig), Speer (einhändig), Stoßspeer (zweihändig), Wurmspieß (zweihändig), Wurfspeer, improvisiert: Turnierlanze , improvisiert: Kriegslanze | E14: D | F14: -3
A15: Nahkampf | B15: Stäbe | C15: {=_xlfn.TEXTJOIN(", ",,_xlfn._xlws.FILTER(Tabelle2[Waffe],Tabelle2[Talent]=Kampftalente!B15))} -> Kampfstab, Zweililien, Magierstab | E15: D | F15: -2
A16: Nahkampf | B16: Zweihandflegel | C16: {=_xlfn.TEXTJOIN(", ",,_xlfn._xlws.FILTER(Tabelle2[Waffe],Tabelle2[Talent]=Kampftalente!B16))} -> Kriegsflegel, improvisiert: Dreschflegel | E16: D | F16: -3
A17: Nahkampf | B17: Zweihand_Hiebwaffen | C17: {=_xlfn.TEXTJOIN(", ",,_xlfn._xlws.FILTER(Tabelle2[Waffe],Tabelle2[Talent]=Kampftalente!B17))} -> Barbarenstreitaxt, EchsischeAxt, Felsspalter, Gruufhai, Kriegshammer, Langaxt, Orknase, Pailos, Schnitter, WarunkerHammer, Zwergenschlägel, Spitzhacke, Vorschlaghammer, improvisiert: Holzfälleraxt | E17: D | F17: -3
A18: Nahkampf | B18: Zweihandschwerter_Säbel | C18: {=_xlfn.TEXTJOIN(", ",,_xlfn._xlws.FILTER(Tabelle2[Waffe],Tabelle2[Talent]=Kampftalente!B18))} -> Andergaster, Anderthalbhänder, Boronssichel, Doppelkhunchomer, Großer Sklaventod, Rondrakamm, Tuzakmesser, Zweihänder, improvisiert: Richtschwert | E18: E | F18: -2
A19: Fernkampf | B19: Armbrust | C19: {=_xlfn.TEXTJOIN(", ",,_xlfn._xlws.FILTER(Tabelle2[Waffe],Tabelle2[Talent]=Kampftalente!B19))} -> Leichte Armbrust, Eisenwalder, Balestrina, Schwere Armbrust, Balläster, Arbalone, Arbalette, Balestra | E19: C | F19: -5
A20: Fernkampf | B20: Belagerungswaffen | C20: {=_xlfn.TEXTJOIN(", ",,_xlfn._xlws.FILTER(Tabelle2[Waffe],Tabelle2[Talent]=Kampftalente!B20))} -> Ballistische Schleudergeräte (Onager, Zyklop), Hornisse, Torsionsschleudern (Aal, Rotze), Drachenmäuler und Belagerungs-Armbrüste | E20: D | F20: -
A21: Fernkampf | B21: Blasrohr | C21: {=_xlfn.TEXTJOIN(", ",,_xlfn._xlws.FILTER(Tabelle2[Waffe],Tabelle2[Talent]=Kampftalente!B21))} -> Blasrohr | E21: D | F21: -5
A22: Fernkampf | B22: Bogen | C22: {=_xlfn.TEXTJOIN(", ",,_xlfn._xlws.FILTER(Tabelle2[Waffe],Tabelle2[Talent]=Kampftalente!B22))} -> Kurzbogen , Kompositbogen, Elfenbogen, Kriegsbogen, Langbogen, Orkischer Reiterbogen | E22: E | F22: -3
A23: Fernkampf | B23: Diskus | C23: {=_xlfn.TEXTJOIN(", ",,_xlfn._xlws.FILTER(Tabelle2[Waffe],Tabelle2[Talent]=Kampftalente!B23))} -> Diskus, Kampfdiskus | E23: D | F23: -2
A24: Fernkampf | B24: Peitsche | C24: {=_xlfn.TEXTJOIN(", ",,_xlfn._xlws.FILTER(Tabelle2[Waffe],Tabelle2[Talent]=Kampftalente!B24))} -> Peitsche | E24: E | F24: -1
A25: Fernkampf | B25: Schleuder | C25: {=_xlfn.TEXTJOIN(", ",,_xlfn._xlws.FILTER(Tabelle2[Waffe],Tabelle2[Talent]=Kampftalente!B25))} -> Schleuder, Fledermaus, Lasso, Leichtes Wurfnetz, Schweres Wurfnetz, Wurfhaken, Enterhaken, improvisiert: Kleines Fischernetz | E25: E | F25: -2
A26: Fernkampf | B26: Wurfbeile | C26: {=_xlfn.TEXTJOIN(", ",,_xlfn._xlws.FILTER(Tabelle2[Waffe],Tabelle2[Talent]=Kampftalente!B26))} -> Wurfbeil, Wurfkeule, Schneidzahn, improvisiert: Stein, Flasche | E26: D | F26: -2
A27: Fernkampf | B27: Wurfmesser | C27: {=_xlfn.TEXTJOIN(", ",,_xlfn._xlws.FILTER(Tabelle2[Waffe],Tabelle2[Talent]=Kampftalente!B27))} -> Borndorn, Wurfmesser, Wurfdolch, Wurfpfeil, Wurfstern, Wurfscheibe, Wurfring, improvisiert: verschiedene Messer und Dolche | E27: D | F27: -3
A28: Fernkampf | B28: Wurfspeere | C28: {=_xlfn.TEXTJOIN(", ",,_xlfn._xlws.FILTER(Tabelle2[Waffe],Tabelle2[Talent]=Kampftalente!B28))} -> Efferdbart, Granatapfel, Holzspeer, Speer, Speerschleuder, Stabschleuder, Wurfspeer, improvisiert: Dschadra | E28: C | F28: -2
